WARNING 2015-08-29 14:02:11,837 Not Found: /
WARNING 2015-08-29 14:02:11,837 Not Found: /
ERROR 2015-08-29 14:18:00,121 Internal Server Error: /
Traceback (most recent call last):
  File "C:\Python34\lib\site-packages\django\core\urlresolvers.py", line 394, in urlconf_module
    return self._urlconf_module
AttributeError: 'RegexURLResolver' object has no attribute '_urlconf_module'

During handling of the above exception, another exception occurred:

Traceback (most recent call last):
  File "C:\Python34\lib\site-packages\django\core\handlers\base.py", line 119, in get_response
    resolver_match = resolver.resolve(request.path_info)
  File "C:\Python34\lib\site-packages\django\core\urlresolvers.py", line 366, in resolve
    for pattern in self.url_patterns:
  File "C:\Python34\lib\site-packages\django\core\urlresolvers.py", line 402, in url_patterns
    patterns = getattr(self.urlconf_module, "urlpatterns", self.urlconf_module)
  File "C:\Python34\lib\site-packages\django\core\urlresolvers.py", line 396, in urlconf_module
    self._urlconf_module = import_module(self.urlconf_name)
  File "C:\Python34\lib\importlib\__init__.py", line 109, in import_module
    return _bootstrap._gcd_import(name[level:], package, level)
  File "<frozen importlib._bootstrap>", line 2254, in _gcd_import
  File "<frozen importlib._bootstrap>", line 2237, in _find_and_load
  File "<frozen importlib._bootstrap>", line 2226, in _find_and_load_unlocked
  File "<frozen importlib._bootstrap>", line 1200, in _load_unlocked
  File "<frozen importlib._bootstrap>", line 1129, in _exec
  File "<frozen importlib._bootstrap>", line 1471, in exec_module
  File "<frozen importlib._bootstrap>", line 321, in _call_with_frames_removed
  File "C:\Users\Timot\Documents\GitHub\EasyA_Web\EasyA_Web\urls.py", line 5, in <module>
    url(r'^account/', include('account.urls')),
  File "C:\Python34\lib\site-packages\django\conf\urls\__init__.py", line 33, in include
    urlconf_module = import_module(urlconf_module)
  File "C:\Python34\lib\importlib\__init__.py", line 109, in import_module
    return _bootstrap._gcd_import(name[level:], package, level)
  File "<frozen importlib._bootstrap>", line 2254, in _gcd_import
  File "<frozen importlib._bootstrap>", line 2237, in _find_and_load
  File "<frozen importlib._bootstrap>", line 2226, in _find_and_load_unlocked
  File "<frozen importlib._bootstrap>", line 1200, in _load_unlocked
  File "<frozen importlib._bootstrap>", line 1129, in _exec
  File "<frozen importlib._bootstrap>", line 1471, in exec_module
  File "<frozen importlib._bootstrap>", line 321, in _call_with_frames_removed
  File "C:\Users\Timot\Documents\GitHub\EasyA_Web\account\urls.py", line 5, in <module>
    url(r'^$', views.index, name='index'),
AttributeError: 'module' object has no attribute 'index'
ERROR 2015-08-29 14:18:00,121 Internal Server Error: /
Traceback (most recent call last):
  File "C:\Python34\lib\site-packages\django\core\urlresolvers.py", line 394, in urlconf_module
    return self._urlconf_module
AttributeError: 'RegexURLResolver' object has no attribute '_urlconf_module'

During handling of the above exception, another exception occurred:

Traceback (most recent call last):
  File "C:\Python34\lib\site-packages\django\core\handlers\base.py", line 119, in get_response
    resolver_match = resolver.resolve(request.path_info)
  File "C:\Python34\lib\site-packages\django\core\urlresolvers.py", line 366, in resolve
    for pattern in self.url_patterns:
  File "C:\Python34\lib\site-packages\django\core\urlresolvers.py", line 402, in url_patterns
    patterns = getattr(self.urlconf_module, "urlpatterns", self.urlconf_module)
  File "C:\Python34\lib\site-packages\django\core\urlresolvers.py", line 396, in urlconf_module
    self._urlconf_module = import_module(self.urlconf_name)
  File "C:\Python34\lib\importlib\__init__.py", line 109, in import_module
    return _bootstrap._gcd_import(name[level:], package, level)
  File "<frozen importlib._bootstrap>", line 2254, in _gcd_import
  File "<frozen importlib._bootstrap>", line 2237, in _find_and_load
  File "<frozen importlib._bootstrap>", line 2226, in _find_and_load_unlocked
  File "<frozen importlib._bootstrap>", line 1200, in _load_unlocked
  File "<frozen importlib._bootstrap>", line 1129, in _exec
  File "<frozen importlib._bootstrap>", line 1471, in exec_module
  File "<frozen importlib._bootstrap>", line 321, in _call_with_frames_removed
  File "C:\Users\Timot\Documents\GitHub\EasyA_Web\EasyA_Web\urls.py", line 5, in <module>
    url(r'^account/', include('account.urls')),
  File "C:\Python34\lib\site-packages\django\conf\urls\__init__.py", line 33, in include
    urlconf_module = import_module(urlconf_module)
  File "C:\Python34\lib\importlib\__init__.py", line 109, in import_module
    return _bootstrap._gcd_import(name[level:], package, level)
  File "<frozen importlib._bootstrap>", line 2254, in _gcd_import
  File "<frozen importlib._bootstrap>", line 2237, in _find_and_load
  File "<frozen importlib._bootstrap>", line 2226, in _find_and_load_unlocked
  File "<frozen importlib._bootstrap>", line 1200, in _load_unlocked
  File "<frozen importlib._bootstrap>", line 1129, in _exec
  File "<frozen importlib._bootstrap>", line 1471, in exec_module
  File "<frozen importlib._bootstrap>", line 321, in _call_with_frames_removed
  File "C:\Users\Timot\Documents\GitHub\EasyA_Web\account\urls.py", line 5, in <module>
    url(r'^$', views.index, name='index'),
AttributeError: 'module' object has no attribute 'index'
ERROR 2015-08-29 14:18:00,399 Internal Server Error: /favicon.ico
Traceback (most recent call last):
  File "C:\Python34\lib\site-packages\django\core\urlresolvers.py", line 394, in urlconf_module
    return self._urlconf_module
AttributeError: 'RegexURLResolver' object has no attribute '_urlconf_module'

During handling of the above exception, another exception occurred:

Traceback (most recent call last):
  File "C:\Python34\lib\site-packages\django\core\handlers\base.py", line 108, in get_response
    response = middleware_method(request)
  File "C:\Python34\lib\site-packages\django\middleware\common.py", line 74, in process_request
    if (not urlresolvers.is_valid_path(request.path_info, urlconf) and
  File "C:\Python34\lib\site-packages\django\core\urlresolvers.py", line 647, in is_valid_path
    resolve(path, urlconf)
  File "C:\Python34\lib\site-packages\django\core\urlresolvers.py", line 522, in resolve
    return get_resolver(urlconf).resolve(path)
  File "C:\Python34\lib\site-packages\django\core\urlresolvers.py", line 366, in resolve
    for pattern in self.url_patterns:
  File "C:\Python34\lib\site-packages\django\core\urlresolvers.py", line 402, in url_patterns
    patterns = getattr(self.urlconf_module, "urlpatterns", self.urlconf_module)
  File "C:\Python34\lib\site-packages\django\core\urlresolvers.py", line 396, in urlconf_module
    self._urlconf_module = import_module(self.urlconf_name)
  File "C:\Python34\lib\importlib\__init__.py", line 109, in import_module
    return _bootstrap._gcd_import(name[level:], package, level)
  File "<frozen importlib._bootstrap>", line 2254, in _gcd_import
  File "<frozen importlib._bootstrap>", line 2237, in _find_and_load
  File "<frozen importlib._bootstrap>", line 2226, in _find_and_load_unlocked
  File "<frozen importlib._bootstrap>", line 1200, in _load_unlocked
  File "<frozen importlib._bootstrap>", line 1129, in _exec
  File "<frozen importlib._bootstrap>", line 1471, in exec_module
  File "<frozen importlib._bootstrap>", line 321, in _call_with_frames_removed
  File "C:\Users\Timot\Documents\GitHub\EasyA_Web\EasyA_Web\urls.py", line 5, in <module>
    url(r'^account/', include('account.urls')),
  File "C:\Python34\lib\site-packages\django\conf\urls\__init__.py", line 33, in include
    urlconf_module = import_module(urlconf_module)
  File "C:\Python34\lib\importlib\__init__.py", line 109, in import_module
    return _bootstrap._gcd_import(name[level:], package, level)
  File "<frozen importlib._bootstrap>", line 2254, in _gcd_import
  File "<frozen importlib._bootstrap>", line 2237, in _find_and_load
  File "<frozen importlib._bootstrap>", line 2226, in _find_and_load_unlocked
  File "<frozen importlib._bootstrap>", line 1200, in _load_unlocked
  File "<frozen importlib._bootstrap>", line 1129, in _exec
  File "<frozen importlib._bootstrap>", line 1471, in exec_module
  File "<frozen importlib._bootstrap>", line 321, in _call_with_frames_removed
  File "C:\Users\Timot\Documents\GitHub\EasyA_Web\account\urls.py", line 5, in <module>
    url(r'^$', views.index, name='index'),
AttributeError: 'module' object has no attribute 'index'
ERROR 2015-08-29 14:18:00,399 Internal Server Error: /favicon.ico
Traceback (most recent call last):
  File "C:\Python34\lib\site-packages\django\core\urlresolvers.py", line 394, in urlconf_module
    return self._urlconf_module
AttributeError: 'RegexURLResolver' object has no attribute '_urlconf_module'

During handling of the above exception, another exception occurred:

Traceback (most recent call last):
  File "C:\Python34\lib\site-packages\django\core\handlers\base.py", line 108, in get_response
    response = middleware_method(request)
  File "C:\Python34\lib\site-packages\django\middleware\common.py", line 74, in process_request
    if (not urlresolvers.is_valid_path(request.path_info, urlconf) and
  File "C:\Python34\lib\site-packages\django\core\urlresolvers.py", line 647, in is_valid_path
    resolve(path, urlconf)
  File "C:\Python34\lib\site-packages\django\core\urlresolvers.py", line 522, in resolve
    return get_resolver(urlconf).resolve(path)
  File "C:\Python34\lib\site-packages\django\core\urlresolvers.py", line 366, in resolve
    for pattern in self.url_patterns:
  File "C:\Python34\lib\site-packages\django\core\urlresolvers.py", line 402, in url_patterns
    patterns = getattr(self.urlconf_module, "urlpatterns", self.urlconf_module)
  File "C:\Python34\lib\site-packages\django\core\urlresolvers.py", line 396, in urlconf_module
    self._urlconf_module = import_module(self.urlconf_name)
  File "C:\Python34\lib\importlib\__init__.py", line 109, in import_module
    return _bootstrap._gcd_import(name[level:], package, level)
  File "<frozen importlib._bootstrap>", line 2254, in _gcd_import
  File "<frozen importlib._bootstrap>", line 2237, in _find_and_load
  File "<frozen importlib._bootstrap>", line 2226, in _find_and_load_unlocked
  File "<frozen importlib._bootstrap>", line 1200, in _load_unlocked
  File "<frozen importlib._bootstrap>", line 1129, in _exec
  File "<frozen importlib._bootstrap>", line 1471, in exec_module
  File "<frozen importlib._bootstrap>", line 321, in _call_with_frames_removed
  File "C:\Users\Timot\Documents\GitHub\EasyA_Web\EasyA_Web\urls.py", line 5, in <module>
    url(r'^account/', include('account.urls')),
  File "C:\Python34\lib\site-packages\django\conf\urls\__init__.py", line 33, in include
    urlconf_module = import_module(urlconf_module)
  File "C:\Python34\lib\importlib\__init__.py", line 109, in import_module
    return _bootstrap._gcd_import(name[level:], package, level)
  File "<frozen importlib._bootstrap>", line 2254, in _gcd_import
  File "<frozen importlib._bootstrap>", line 2237, in _find_and_load
  File "<frozen importlib._bootstrap>", line 2226, in _find_and_load_unlocked
  File "<frozen importlib._bootstrap>", line 1200, in _load_unlocked
  File "<frozen importlib._bootstrap>", line 1129, in _exec
  File "<frozen importlib._bootstrap>", line 1471, in exec_module
  File "<frozen importlib._bootstrap>", line 321, in _call_with_frames_removed
  File "C:\Users\Timot\Documents\GitHub\EasyA_Web\account\urls.py", line 5, in <module>
    url(r'^$', views.index, name='index'),
AttributeError: 'module' object has no attribute 'index'
ERROR 2015-08-29 14:18:07,223 Internal Server Error: /index
Traceback (most recent call last):
  File "C:\Python34\lib\site-packages\django\core\urlresolvers.py", line 394, in urlconf_module
    return self._urlconf_module
AttributeError: 'RegexURLResolver' object has no attribute '_urlconf_module'

During handling of the above exception, another exception occurred:

Traceback (most recent call last):
  File "C:\Python34\lib\site-packages\django\core\handlers\base.py", line 108, in get_response
    response = middleware_method(request)
  File "C:\Python34\lib\site-packages\django\middleware\common.py", line 74, in process_request
    if (not urlresolvers.is_valid_path(request.path_info, urlconf) and
  File "C:\Python34\lib\site-packages\django\core\urlresolvers.py", line 647, in is_valid_path
    resolve(path, urlconf)
  File "C:\Python34\lib\site-packages\django\core\urlresolvers.py", line 522, in resolve
    return get_resolver(urlconf).resolve(path)
  File "C:\Python34\lib\site-packages\django\core\urlresolvers.py", line 366, in resolve
    for pattern in self.url_patterns:
  File "C:\Python34\lib\site-packages\django\core\urlresolvers.py", line 402, in url_patterns
    patterns = getattr(self.urlconf_module, "urlpatterns", self.urlconf_module)
  File "C:\Python34\lib\site-packages\django\core\urlresolvers.py", line 396, in urlconf_module
    self._urlconf_module = import_module(self.urlconf_name)
  File "C:\Python34\lib\importlib\__init__.py", line 109, in import_module
    return _bootstrap._gcd_import(name[level:], package, level)
  File "<frozen importlib._bootstrap>", line 2254, in _gcd_import
  File "<frozen importlib._bootstrap>", line 2237, in _find_and_load
  File "<frozen importlib._bootstrap>", line 2226, in _find_and_load_unlocked
  File "<frozen importlib._bootstrap>", line 1200, in _load_unlocked
  File "<frozen importlib._bootstrap>", line 1129, in _exec
  File "<frozen importlib._bootstrap>", line 1471, in exec_module
  File "<frozen importlib._bootstrap>", line 321, in _call_with_frames_removed
  File "C:\Users\Timot\Documents\GitHub\EasyA_Web\EasyA_Web\urls.py", line 5, in <module>
    url(r'^account/', include('account.urls')),
  File "C:\Python34\lib\site-packages\django\conf\urls\__init__.py", line 33, in include
    urlconf_module = import_module(urlconf_module)
  File "C:\Python34\lib\importlib\__init__.py", line 109, in import_module
    return _bootstrap._gcd_import(name[level:], package, level)
  File "<frozen importlib._bootstrap>", line 2254, in _gcd_import
  File "<frozen importlib._bootstrap>", line 2237, in _find_and_load
  File "<frozen importlib._bootstrap>", line 2226, in _find_and_load_unlocked
  File "<frozen importlib._bootstrap>", line 1200, in _load_unlocked
  File "<frozen importlib._bootstrap>", line 1129, in _exec
  File "<frozen importlib._bootstrap>", line 1471, in exec_module
  File "<frozen importlib._bootstrap>", line 321, in _call_with_frames_removed
  File "C:\Users\Timot\Documents\GitHub\EasyA_Web\account\urls.py", line 5, in <module>
    url(r'^$', views.index, name='index'),
AttributeError: 'module' object has no attribute 'index'
ERROR 2015-08-29 14:18:07,223 Internal Server Error: /index
Traceback (most recent call last):
  File "C:\Python34\lib\site-packages\django\core\urlresolvers.py", line 394, in urlconf_module
    return self._urlconf_module
AttributeError: 'RegexURLResolver' object has no attribute '_urlconf_module'

During handling of the above exception, another exception occurred:

Traceback (most recent call last):
  File "C:\Python34\lib\site-packages\django\core\handlers\base.py", line 108, in get_response
    response = middleware_method(request)
  File "C:\Python34\lib\site-packages\django\middleware\common.py", line 74, in process_request
    if (not urlresolvers.is_valid_path(request.path_info, urlconf) and
  File "C:\Python34\lib\site-packages\django\core\urlresolvers.py", line 647, in is_valid_path
    resolve(path, urlconf)
  File "C:\Python34\lib\site-packages\django\core\urlresolvers.py", line 522, in resolve
    return get_resolver(urlconf).resolve(path)
  File "C:\Python34\lib\site-packages\django\core\urlresolvers.py", line 366, in resolve
    for pattern in self.url_patterns:
  File "C:\Python34\lib\site-packages\django\core\urlresolvers.py", line 402, in url_patterns
    patterns = getattr(self.urlconf_module, "urlpatterns", self.urlconf_module)
  File "C:\Python34\lib\site-packages\django\core\urlresolvers.py", line 396, in urlconf_module
    self._urlconf_module = import_module(self.urlconf_name)
  File "C:\Python34\lib\importlib\__init__.py", line 109, in import_module
    return _bootstrap._gcd_import(name[level:], package, level)
  File "<frozen importlib._bootstrap>", line 2254, in _gcd_import
  File "<frozen importlib._bootstrap>", line 2237, in _find_and_load
  File "<frozen importlib._bootstrap>", line 2226, in _find_and_load_unlocked
  File "<frozen importlib._bootstrap>", line 1200, in _load_unlocked
  File "<frozen importlib._bootstrap>", line 1129, in _exec
  File "<frozen importlib._bootstrap>", line 1471, in exec_module
  File "<frozen importlib._bootstrap>", line 321, in _call_with_frames_removed
  File "C:\Users\Timot\Documents\GitHub\EasyA_Web\EasyA_Web\urls.py", line 5, in <module>
    url(r'^account/', include('account.urls')),
  File "C:\Python34\lib\site-packages\django\conf\urls\__init__.py", line 33, in include
    urlconf_module = import_module(urlconf_module)
  File "C:\Python34\lib\importlib\__init__.py", line 109, in import_module
    return _bootstrap._gcd_import(name[level:], package, level)
  File "<frozen importlib._bootstrap>", line 2254, in _gcd_import
  File "<frozen importlib._bootstrap>", line 2237, in _find_and_load
  File "<frozen importlib._bootstrap>", line 2226, in _find_and_load_unlocked
  File "<frozen importlib._bootstrap>", line 1200, in _load_unlocked
  File "<frozen importlib._bootstrap>", line 1129, in _exec
  File "<frozen importlib._bootstrap>", line 1471, in exec_module
  File "<frozen importlib._bootstrap>", line 321, in _call_with_frames_removed
  File "C:\Users\Timot\Documents\GitHub\EasyA_Web\account\urls.py", line 5, in <module>
    url(r'^$', views.index, name='index'),
AttributeError: 'module' object has no attribute 'index'
ERROR 2015-08-29 14:18:07,460 Internal Server Error: /favicon.ico
Traceback (most recent call last):
  File "C:\Python34\lib\site-packages\django\core\urlresolvers.py", line 394, in urlconf_module
    return self._urlconf_module
AttributeError: 'RegexURLResolver' object has no attribute '_urlconf_module'

During handling of the above exception, another exception occurred:

Traceback (most recent call last):
  File "C:\Python34\lib\site-packages\django\core\handlers\base.py", line 108, in get_response
    response = middleware_method(request)
  File "C:\Python34\lib\site-packages\django\middleware\common.py", line 74, in process_request
    if (not urlresolvers.is_valid_path(request.path_info, urlconf) and
  File "C:\Python34\lib\site-packages\django\core\urlresolvers.py", line 647, in is_valid_path
    resolve(path, urlconf)
  File "C:\Python34\lib\site-packages\django\core\urlresolvers.py", line 522, in resolve
    return get_resolver(urlconf).resolve(path)
  File "C:\Python34\lib\site-packages\django\core\urlresolvers.py", line 366, in resolve
    for pattern in self.url_patterns:
  File "C:\Python34\lib\site-packages\django\core\urlresolvers.py", line 402, in url_patterns
    patterns = getattr(self.urlconf_module, "urlpatterns", self.urlconf_module)
  File "C:\Python34\lib\site-packages\django\core\urlresolvers.py", line 396, in urlconf_module
    self._urlconf_module = import_module(self.urlconf_name)
  File "C:\Python34\lib\importlib\__init__.py", line 109, in import_module
    return _bootstrap._gcd_import(name[level:], package, level)
  File "<frozen importlib._bootstrap>", line 2254, in _gcd_import
  File "<frozen importlib._bootstrap>", line 2237, in _find_and_load
  File "<frozen importlib._bootstrap>", line 2226, in _find_and_load_unlocked
  File "<frozen importlib._bootstrap>", line 1200, in _load_unlocked
  File "<frozen importlib._bootstrap>", line 1129, in _exec
  File "<frozen importlib._bootstrap>", line 1471, in exec_module
  File "<frozen importlib._bootstrap>", line 321, in _call_with_frames_removed
  File "C:\Users\Timot\Documents\GitHub\EasyA_Web\EasyA_Web\urls.py", line 5, in <module>
    url(r'^account/', include('account.urls')),
  File "C:\Python34\lib\site-packages\django\conf\urls\__init__.py", line 33, in include
    urlconf_module = import_module(urlconf_module)
  File "C:\Python34\lib\importlib\__init__.py", line 109, in import_module
    return _bootstrap._gcd_import(name[level:], package, level)
  File "<frozen importlib._bootstrap>", line 2254, in _gcd_import
  File "<frozen importlib._bootstrap>", line 2237, in _find_and_load
  File "<frozen importlib._bootstrap>", line 2226, in _find_and_load_unlocked
  File "<frozen importlib._bootstrap>", line 1200, in _load_unlocked
  File "<frozen importlib._bootstrap>", line 1129, in _exec
  File "<frozen importlib._bootstrap>", line 1471, in exec_module
  File "<frozen importlib._bootstrap>", line 321, in _call_with_frames_removed
  File "C:\Users\Timot\Documents\GitHub\EasyA_Web\account\urls.py", line 5, in <module>
    url(r'^$', views.index, name='index'),
AttributeError: 'module' object has no attribute 'index'
ERROR 2015-08-29 14:18:07,460 Internal Server Error: /favicon.ico
Traceback (most recent call last):
  File "C:\Python34\lib\site-packages\django\core\urlresolvers.py", line 394, in urlconf_module
    return self._urlconf_module
AttributeError: 'RegexURLResolver' object has no attribute '_urlconf_module'

During handling of the above exception, another exception occurred:

Traceback (most recent call last):
  File "C:\Python34\lib\site-packages\django\core\handlers\base.py", line 108, in get_response
    response = middleware_method(request)
  File "C:\Python34\lib\site-packages\django\middleware\common.py", line 74, in process_request
    if (not urlresolvers.is_valid_path(request.path_info, urlconf) and
  File "C:\Python34\lib\site-packages\django\core\urlresolvers.py", line 647, in is_valid_path
    resolve(path, urlconf)
  File "C:\Python34\lib\site-packages\django\core\urlresolvers.py", line 522, in resolve
    return get_resolver(urlconf).resolve(path)
  File "C:\Python34\lib\site-packages\django\core\urlresolvers.py", line 366, in resolve
    for pattern in self.url_patterns:
  File "C:\Python34\lib\site-packages\django\core\urlresolvers.py", line 402, in url_patterns
    patterns = getattr(self.urlconf_module, "urlpatterns", self.urlconf_module)
  File "C:\Python34\lib\site-packages\django\core\urlresolvers.py", line 396, in urlconf_module
    self._urlconf_module = import_module(self.urlconf_name)
  File "C:\Python34\lib\importlib\__init__.py", line 109, in import_module
    return _bootstrap._gcd_import(name[level:], package, level)
  File "<frozen importlib._bootstrap>", line 2254, in _gcd_import
  File "<frozen importlib._bootstrap>", line 2237, in _find_and_load
  File "<frozen importlib._bootstrap>", line 2226, in _find_and_load_unlocked
  File "<frozen importlib._bootstrap>", line 1200, in _load_unlocked
  File "<frozen importlib._bootstrap>", line 1129, in _exec
  File "<frozen importlib._bootstrap>", line 1471, in exec_module
  File "<frozen importlib._bootstrap>", line 321, in _call_with_frames_removed
  File "C:\Users\Timot\Documents\GitHub\EasyA_Web\EasyA_Web\urls.py", line 5, in <module>
    url(r'^account/', include('account.urls')),
  File "C:\Python34\lib\site-packages\django\conf\urls\__init__.py", line 33, in include
    urlconf_module = import_module(urlconf_module)
  File "C:\Python34\lib\importlib\__init__.py", line 109, in import_module
    return _bootstrap._gcd_import(name[level:], package, level)
  File "<frozen importlib._bootstrap>", line 2254, in _gcd_import
  File "<frozen importlib._bootstrap>", line 2237, in _find_and_load
  File "<frozen importlib._bootstrap>", line 2226, in _find_and_load_unlocked
  File "<frozen importlib._bootstrap>", line 1200, in _load_unlocked
  File "<frozen importlib._bootstrap>", line 1129, in _exec
  File "<frozen importlib._bootstrap>", line 1471, in exec_module
  File "<frozen importlib._bootstrap>", line 321, in _call_with_frames_removed
  File "C:\Users\Timot\Documents\GitHub\EasyA_Web\account\urls.py", line 5, in <module>
    url(r'^$', views.index, name='index'),
AttributeError: 'module' object has no attribute 'index'
ERROR 2015-08-29 14:18:19,490 Internal Server Error: /index/
Traceback (most recent call last):
  File "C:\Python34\lib\site-packages\django\core\urlresolvers.py", line 394, in urlconf_module
    return self._urlconf_module
AttributeError: 'RegexURLResolver' object has no attribute '_urlconf_module'

During handling of the above exception, another exception occurred:

Traceback (most recent call last):
  File "C:\Python34\lib\site-packages\django\core\handlers\base.py", line 119, in get_response
    resolver_match = resolver.resolve(request.path_info)
  File "C:\Python34\lib\site-packages\django\core\urlresolvers.py", line 366, in resolve
    for pattern in self.url_patterns:
  File "C:\Python34\lib\site-packages\django\core\urlresolvers.py", line 402, in url_patterns
    patterns = getattr(self.urlconf_module, "urlpatterns", self.urlconf_module)
  File "C:\Python34\lib\site-packages\django\core\urlresolvers.py", line 396, in urlconf_module
    self._urlconf_module = import_module(self.urlconf_name)
  File "C:\Python34\lib\importlib\__init__.py", line 109, in import_module
    return _bootstrap._gcd_import(name[level:], package, level)
  File "<frozen importlib._bootstrap>", line 2254, in _gcd_import
  File "<frozen importlib._bootstrap>", line 2237, in _find_and_load
  File "<frozen importlib._bootstrap>", line 2226, in _find_and_load_unlocked
  File "<frozen importlib._bootstrap>", line 1200, in _load_unlocked
  File "<frozen importlib._bootstrap>", line 1129, in _exec
  File "<frozen importlib._bootstrap>", line 1471, in exec_module
  File "<frozen importlib._bootstrap>", line 321, in _call_with_frames_removed
  File "C:\Users\Timot\Documents\GitHub\EasyA_Web\EasyA_Web\urls.py", line 5, in <module>
    url(r'^account/', include('account.urls')),
  File "C:\Python34\lib\site-packages\django\conf\urls\__init__.py", line 33, in include
    urlconf_module = import_module(urlconf_module)
  File "C:\Python34\lib\importlib\__init__.py", line 109, in import_module
    return _bootstrap._gcd_import(name[level:], package, level)
  File "<frozen importlib._bootstrap>", line 2254, in _gcd_import
  File "<frozen importlib._bootstrap>", line 2237, in _find_and_load
  File "<frozen importlib._bootstrap>", line 2226, in _find_and_load_unlocked
  File "<frozen importlib._bootstrap>", line 1200, in _load_unlocked
  File "<frozen importlib._bootstrap>", line 1129, in _exec
  File "<frozen importlib._bootstrap>", line 1471, in exec_module
  File "<frozen importlib._bootstrap>", line 321, in _call_with_frames_removed
  File "C:\Users\Timot\Documents\GitHub\EasyA_Web\account\urls.py", line 5, in <module>
    url(r'^$', views.index, name='index'),
AttributeError: 'module' object has no attribute 'index'
ERROR 2015-08-29 14:18:19,490 Internal Server Error: /index/
Traceback (most recent call last):
  File "C:\Python34\lib\site-packages\django\core\urlresolvers.py", line 394, in urlconf_module
    return self._urlconf_module
AttributeError: 'RegexURLResolver' object has no attribute '_urlconf_module'

During handling of the above exception, another exception occurred:

Traceback (most recent call last):
  File "C:\Python34\lib\site-packages\django\core\handlers\base.py", line 119, in get_response
    resolver_match = resolver.resolve(request.path_info)
  File "C:\Python34\lib\site-packages\django\core\urlresolvers.py", line 366, in resolve
    for pattern in self.url_patterns:
  File "C:\Python34\lib\site-packages\django\core\urlresolvers.py", line 402, in url_patterns
    patterns = getattr(self.urlconf_module, "urlpatterns", self.urlconf_module)
  File "C:\Python34\lib\site-packages\django\core\urlresolvers.py", line 396, in urlconf_module
    self._urlconf_module = import_module(self.urlconf_name)
  File "C:\Python34\lib\importlib\__init__.py", line 109, in import_module
    return _bootstrap._gcd_import(name[level:], package, level)
  File "<frozen importlib._bootstrap>", line 2254, in _gcd_import
  File "<frozen importlib._bootstrap>", line 2237, in _find_and_load
  File "<frozen importlib._bootstrap>", line 2226, in _find_and_load_unlocked
  File "<frozen importlib._bootstrap>", line 1200, in _load_unlocked
  File "<frozen importlib._bootstrap>", line 1129, in _exec
  File "<frozen importlib._bootstrap>", line 1471, in exec_module
  File "<frozen importlib._bootstrap>", line 321, in _call_with_frames_removed
  File "C:\Users\Timot\Documents\GitHub\EasyA_Web\EasyA_Web\urls.py", line 5, in <module>
    url(r'^account/', include('account.urls')),
  File "C:\Python34\lib\site-packages\django\conf\urls\__init__.py", line 33, in include
    urlconf_module = import_module(urlconf_module)
  File "C:\Python34\lib\importlib\__init__.py", line 109, in import_module
    return _bootstrap._gcd_import(name[level:], package, level)
  File "<frozen importlib._bootstrap>", line 2254, in _gcd_import
  File "<frozen importlib._bootstrap>", line 2237, in _find_and_load
  File "<frozen importlib._bootstrap>", line 2226, in _find_and_load_unlocked
  File "<frozen importlib._bootstrap>", line 1200, in _load_unlocked
  File "<frozen importlib._bootstrap>", line 1129, in _exec
  File "<frozen importlib._bootstrap>", line 1471, in exec_module
  File "<frozen importlib._bootstrap>", line 321, in _call_with_frames_removed
  File "C:\Users\Timot\Documents\GitHub\EasyA_Web\account\urls.py", line 5, in <module>
    url(r'^$', views.index, name='index'),
AttributeError: 'module' object has no attribute 'index'
ERROR 2015-08-29 14:18:19,654 Internal Server Error: /favicon.ico
Traceback (most recent call last):
  File "C:\Python34\lib\site-packages\django\core\urlresolvers.py", line 394, in urlconf_module
    return self._urlconf_module
AttributeError: 'RegexURLResolver' object has no attribute '_urlconf_module'

During handling of the above exception, another exception occurred:

Traceback (most recent call last):
  File "C:\Python34\lib\site-packages\django\core\handlers\base.py", line 108, in get_response
    response = middleware_method(request)
  File "C:\Python34\lib\site-packages\django\middleware\common.py", line 74, in process_request
    if (not urlresolvers.is_valid_path(request.path_info, urlconf) and
  File "C:\Python34\lib\site-packages\django\core\urlresolvers.py", line 647, in is_valid_path
    resolve(path, urlconf)
  File "C:\Python34\lib\site-packages\django\core\urlresolvers.py", line 522, in resolve
    return get_resolver(urlconf).resolve(path)
  File "C:\Python34\lib\site-packages\django\core\urlresolvers.py", line 366, in resolve
    for pattern in self.url_patterns:
  File "C:\Python34\lib\site-packages\django\core\urlresolvers.py", line 402, in url_patterns
    patterns = getattr(self.urlconf_module, "urlpatterns", self.urlconf_module)
  File "C:\Python34\lib\site-packages\django\core\urlresolvers.py", line 396, in urlconf_module
    self._urlconf_module = import_module(self.urlconf_name)
  File "C:\Python34\lib\importlib\__init__.py", line 109, in import_module
    return _bootstrap._gcd_import(name[level:], package, level)
  File "<frozen importlib._bootstrap>", line 2254, in _gcd_import
  File "<frozen importlib._bootstrap>", line 2237, in _find_and_load
  File "<frozen importlib._bootstrap>", line 2226, in _find_and_load_unlocked
  File "<frozen importlib._bootstrap>", line 1200, in _load_unlocked
  File "<frozen importlib._bootstrap>", line 1129, in _exec
  File "<frozen importlib._bootstrap>", line 1471, in exec_module
  File "<frozen importlib._bootstrap>", line 321, in _call_with_frames_removed
  File "C:\Users\Timot\Documents\GitHub\EasyA_Web\EasyA_Web\urls.py", line 5, in <module>
    url(r'^account/', include('account.urls')),
  File "C:\Python34\lib\site-packages\django\conf\urls\__init__.py", line 33, in include
    urlconf_module = import_module(urlconf_module)
  File "C:\Python34\lib\importlib\__init__.py", line 109, in import_module
    return _bootstrap._gcd_import(name[level:], package, level)
  File "<frozen importlib._bootstrap>", line 2254, in _gcd_import
  File "<frozen importlib._bootstrap>", line 2237, in _find_and_load
  File "<frozen importlib._bootstrap>", line 2226, in _find_and_load_unlocked
  File "<frozen importlib._bootstrap>", line 1200, in _load_unlocked
  File "<frozen importlib._bootstrap>", line 1129, in _exec
  File "<frozen importlib._bootstrap>", line 1471, in exec_module
  File "<frozen importlib._bootstrap>", line 321, in _call_with_frames_removed
  File "C:\Users\Timot\Documents\GitHub\EasyA_Web\account\urls.py", line 5, in <module>
    url(r'^$', views.index, name='index'),
AttributeError: 'module' object has no attribute 'index'
ERROR 2015-08-29 14:18:19,654 Internal Server Error: /favicon.ico
Traceback (most recent call last):
  File "C:\Python34\lib\site-packages\django\core\urlresolvers.py", line 394, in urlconf_module
    return self._urlconf_module
AttributeError: 'RegexURLResolver' object has no attribute '_urlconf_module'

During handling of the above exception, another exception occurred:

Traceback (most recent call last):
  File "C:\Python34\lib\site-packages\django\core\handlers\base.py", line 108, in get_response
    response = middleware_method(request)
  File "C:\Python34\lib\site-packages\django\middleware\common.py", line 74, in process_request
    if (not urlresolvers.is_valid_path(request.path_info, urlconf) and
  File "C:\Python34\lib\site-packages\django\core\urlresolvers.py", line 647, in is_valid_path
    resolve(path, urlconf)
  File "C:\Python34\lib\site-packages\django\core\urlresolvers.py", line 522, in resolve
    return get_resolver(urlconf).resolve(path)
  File "C:\Python34\lib\site-packages\django\core\urlresolvers.py", line 366, in resolve
    for pattern in self.url_patterns:
  File "C:\Python34\lib\site-packages\django\core\urlresolvers.py", line 402, in url_patterns
    patterns = getattr(self.urlconf_module, "urlpatterns", self.urlconf_module)
  File "C:\Python34\lib\site-packages\django\core\urlresolvers.py", line 396, in urlconf_module
    self._urlconf_module = import_module(self.urlconf_name)
  File "C:\Python34\lib\importlib\__init__.py", line 109, in import_module
    return _bootstrap._gcd_import(name[level:], package, level)
  File "<frozen importlib._bootstrap>", line 2254, in _gcd_import
  File "<frozen importlib._bootstrap>", line 2237, in _find_and_load
  File "<frozen importlib._bootstrap>", line 2226, in _find_and_load_unlocked
  File "<frozen importlib._bootstrap>", line 1200, in _load_unlocked
  File "<frozen importlib._bootstrap>", line 1129, in _exec
  File "<frozen importlib._bootstrap>", line 1471, in exec_module
  File "<frozen importlib._bootstrap>", line 321, in _call_with_frames_removed
  File "C:\Users\Timot\Documents\GitHub\EasyA_Web\EasyA_Web\urls.py", line 5, in <module>
    url(r'^account/', include('account.urls')),
  File "C:\Python34\lib\site-packages\django\conf\urls\__init__.py", line 33, in include
    urlconf_module = import_module(urlconf_module)
  File "C:\Python34\lib\importlib\__init__.py", line 109, in import_module
    return _bootstrap._gcd_import(name[level:], package, level)
  File "<frozen importlib._bootstrap>", line 2254, in _gcd_import
  File "<frozen importlib._bootstrap>", line 2237, in _find_and_load
  File "<frozen importlib._bootstrap>", line 2226, in _find_and_load_unlocked
  File "<frozen importlib._bootstrap>", line 1200, in _load_unlocked
  File "<frozen importlib._bootstrap>", line 1129, in _exec
  File "<frozen importlib._bootstrap>", line 1471, in exec_module
  File "<frozen importlib._bootstrap>", line 321, in _call_with_frames_removed
  File "C:\Users\Timot\Documents\GitHub\EasyA_Web\account\urls.py", line 5, in <module>
    url(r'^$', views.index, name='index'),
AttributeError: 'module' object has no attribute 'index'
WARNING 2015-08-29 14:19:10,050 Not Found: /favicon.ico
WARNING 2015-08-29 14:19:10,050 Not Found: /favicon.ico
ERROR 2015-08-29 14:28:08,683 Internal Server Error: /index/
Traceback (most recent call last):
  File "C:\Python34\lib\site-packages\django\core\handlers\base.py", line 132, in get_response
    response = wrapped_callback(request, *callback_args, **callback_kwargs)
  File "C:\Users\Timot\Documents\GitHub\EasyA_Web\index\views.py", line 5, in index
    return render(request, 'index/index.html')
  File "C:\Python34\lib\site-packages\django\shortcuts.py", line 67, in render
    template_name, context, request=request, using=using)
  File "C:\Python34\lib\site-packages\django\template\loader.py", line 98, in render_to_string
    template = get_template(template_name, using=using)
  File "C:\Python34\lib\site-packages\django\template\loader.py", line 46, in get_template
    raise TemplateDoesNotExist(template_name)
django.template.base.TemplateDoesNotExist: index/index.html
ERROR 2015-08-29 14:28:08,683 Internal Server Error: /index/
Traceback (most recent call last):
  File "C:\Python34\lib\site-packages\django\core\handlers\base.py", line 132, in get_response
    response = wrapped_callback(request, *callback_args, **callback_kwargs)
  File "C:\Users\Timot\Documents\GitHub\EasyA_Web\index\views.py", line 5, in index
    return render(request, 'index/index.html')
  File "C:\Python34\lib\site-packages\django\shortcuts.py", line 67, in render
    template_name, context, request=request, using=using)
  File "C:\Python34\lib\site-packages\django\template\loader.py", line 98, in render_to_string
    template = get_template(template_name, using=using)
  File "C:\Python34\lib\site-packages\django\template\loader.py", line 46, in get_template
    raise TemplateDoesNotExist(template_name)
django.template.base.TemplateDoesNotExist: index/index.html
ERROR 2015-08-29 14:28:38,828 Internal Server Error: /index/
Traceback (most recent call last):
  File "C:\Python34\lib\site-packages\django\core\handlers\base.py", line 132, in get_response
    response = wrapped_callback(request, *callback_args, **callback_kwargs)
  File "C:\Users\Timot\Documents\GitHub\EasyA_Web\index\views.py", line 5, in index
    return render(request, 'index/templates/index.html')
  File "C:\Python34\lib\site-packages\django\shortcuts.py", line 67, in render
    template_name, context, request=request, using=using)
  File "C:\Python34\lib\site-packages\django\template\loader.py", line 98, in render_to_string
    template = get_template(template_name, using=using)
  File "C:\Python34\lib\site-packages\django\template\loader.py", line 46, in get_template
    raise TemplateDoesNotExist(template_name)
django.template.base.TemplateDoesNotExist: index/templates/index.html
ERROR 2015-08-29 14:28:38,828 Internal Server Error: /index/
Traceback (most recent call last):
  File "C:\Python34\lib\site-packages\django\core\handlers\base.py", line 132, in get_response
    response = wrapped_callback(request, *callback_args, **callback_kwargs)
  File "C:\Users\Timot\Documents\GitHub\EasyA_Web\index\views.py", line 5, in index
    return render(request, 'index/templates/index.html')
  File "C:\Python34\lib\site-packages\django\shortcuts.py", line 67, in render
    template_name, context, request=request, using=using)
  File "C:\Python34\lib\site-packages\django\template\loader.py", line 98, in render_to_string
    template = get_template(template_name, using=using)
  File "C:\Python34\lib\site-packages\django\template\loader.py", line 46, in get_template
    raise TemplateDoesNotExist(template_name)
django.template.base.TemplateDoesNotExist: index/templates/index.html
ERROR 2015-08-29 14:28:47,714 Internal Server Error: /index/
Traceback (most recent call last):
  File "C:\Python34\lib\site-packages\django\core\handlers\base.py", line 132, in get_response
    response = wrapped_callback(request, *callback_args, **callback_kwargs)
  File "C:\Users\Timot\Documents\GitHub\EasyA_Web\index\views.py", line 5, in index
    return render(request, 'index.html')
  File "C:\Python34\lib\site-packages\django\shortcuts.py", line 67, in render
    template_name, context, request=request, using=using)
  File "C:\Python34\lib\site-packages\django\template\loader.py", line 98, in render_to_string
    template = get_template(template_name, using=using)
  File "C:\Python34\lib\site-packages\django\template\loader.py", line 46, in get_template
    raise TemplateDoesNotExist(template_name)
django.template.base.TemplateDoesNotExist: index.html
ERROR 2015-08-29 14:28:47,714 Internal Server Error: /index/
Traceback (most recent call last):
  File "C:\Python34\lib\site-packages\django\core\handlers\base.py", line 132, in get_response
    response = wrapped_callback(request, *callback_args, **callback_kwargs)
  File "C:\Users\Timot\Documents\GitHub\EasyA_Web\index\views.py", line 5, in index
    return render(request, 'index.html')
  File "C:\Python34\lib\site-packages\django\shortcuts.py", line 67, in render
    template_name, context, request=request, using=using)
  File "C:\Python34\lib\site-packages\django\template\loader.py", line 98, in render_to_string
    template = get_template(template_name, using=using)
  File "C:\Python34\lib\site-packages\django\template\loader.py", line 46, in get_template
    raise TemplateDoesNotExist(template_name)
django.template.base.TemplateDoesNotExist: index.html
ERROR 2015-08-29 14:33:41,878 Internal Server Error: /index/
Traceback (most recent call last):
  File "C:\Python34\lib\site-packages\django\template\utils.py", line 86, in __getitem__
    return self._engines[alias]
KeyError: 'django'

During handling of the above exception, another exception occurred:

Traceback (most recent call last):
  File "C:\Python34\lib\site-packages\django\core\handlers\base.py", line 132, in get_response
    response = wrapped_callback(request, *callback_args, **callback_kwargs)
  File "C:\Users\Timot\Documents\GitHub\EasyA_Web\index\views.py", line 5, in index
    return render(request, 'index.html')
  File "C:\Python34\lib\site-packages\django\shortcuts.py", line 67, in render
    template_name, context, request=request, using=using)
  File "C:\Python34\lib\site-packages\django\template\loader.py", line 98, in render_to_string
    template = get_template(template_name, using=using)
  File "C:\Python34\lib\site-packages\django\template\loader.py", line 29, in get_template
    engines = _engine_list(using)
  File "C:\Python34\lib\site-packages\django\template\loader.py", line 143, in _engine_list
    return engines.all() if using is None else [engines[using]]
  File "C:\Python34\lib\site-packages\django\template\utils.py", line 110, in all
    return [self[alias] for alias in self]
  File "C:\Python34\lib\site-packages\django\template\utils.py", line 110, in <listcomp>
    return [self[alias] for alias in self]
  File "C:\Python34\lib\site-packages\django\template\utils.py", line 101, in __getitem__
    engine = engine_cls(params)
  File "C:\Python34\lib\site-packages\django\template\backends\django.py", line 23, in __init__
    super(DjangoTemplates, self).__init__(params)
  File "C:\Python34\lib\site-packages\django\template\backends\base.py", line 29, in __init__
    "Unknown parameters: {}".format(", ".join(params)))
django.core.exceptions.ImproperlyConfigured: Unknown parameters: TEMPLATE_DEBUG
ERROR 2015-08-29 14:33:41,878 Internal Server Error: /index/
Traceback (most recent call last):
  File "C:\Python34\lib\site-packages\django\template\utils.py", line 86, in __getitem__
    return self._engines[alias]
KeyError: 'django'

During handling of the above exception, another exception occurred:

Traceback (most recent call last):
  File "C:\Python34\lib\site-packages\django\core\handlers\base.py", line 132, in get_response
    response = wrapped_callback(request, *callback_args, **callback_kwargs)
  File "C:\Users\Timot\Documents\GitHub\EasyA_Web\index\views.py", line 5, in index
    return render(request, 'index.html')
  File "C:\Python34\lib\site-packages\django\shortcuts.py", line 67, in render
    template_name, context, request=request, using=using)
  File "C:\Python34\lib\site-packages\django\template\loader.py", line 98, in render_to_string
    template = get_template(template_name, using=using)
  File "C:\Python34\lib\site-packages\django\template\loader.py", line 29, in get_template
    engines = _engine_list(using)
  File "C:\Python34\lib\site-packages\django\template\loader.py", line 143, in _engine_list
    return engines.all() if using is None else [engines[using]]
  File "C:\Python34\lib\site-packages\django\template\utils.py", line 110, in all
    return [self[alias] for alias in self]
  File "C:\Python34\lib\site-packages\django\template\utils.py", line 110, in <listcomp>
    return [self[alias] for alias in self]
  File "C:\Python34\lib\site-packages\django\template\utils.py", line 101, in __getitem__
    engine = engine_cls(params)
  File "C:\Python34\lib\site-packages\django\template\backends\django.py", line 23, in __init__
    super(DjangoTemplates, self).__init__(params)
  File "C:\Python34\lib\site-packages\django\template\backends\base.py", line 29, in __init__
    "Unknown parameters: {}".format(", ".join(params)))
django.core.exceptions.ImproperlyConfigured: Unknown parameters: TEMPLATE_DEBUG
ERROR 2015-08-29 14:34:48,848 Internal Server Error: /index/
Traceback (most recent call last):
  File "C:\Python34\lib\site-packages\django\template\utils.py", line 86, in __getitem__
    return self._engines[alias]
KeyError: 'django'

During handling of the above exception, another exception occurred:

Traceback (most recent call last):
  File "C:\Python34\lib\site-packages\django\core\handlers\base.py", line 132, in get_response
    response = wrapped_callback(request, *callback_args, **callback_kwargs)
  File "C:\Users\Timot\Documents\GitHub\EasyA_Web\index\views.py", line 5, in index
    return render(request, 'index.html')
  File "C:\Python34\lib\site-packages\django\shortcuts.py", line 67, in render
    template_name, context, request=request, using=using)
  File "C:\Python34\lib\site-packages\django\template\loader.py", line 98, in render_to_string
    template = get_template(template_name, using=using)
  File "C:\Python34\lib\site-packages\django\template\loader.py", line 29, in get_template
    engines = _engine_list(using)
  File "C:\Python34\lib\site-packages\django\template\loader.py", line 143, in _engine_list
    return engines.all() if using is None else [engines[using]]
  File "C:\Python34\lib\site-packages\django\template\utils.py", line 110, in all
    return [self[alias] for alias in self]
  File "C:\Python34\lib\site-packages\django\template\utils.py", line 110, in <listcomp>
    return [self[alias] for alias in self]
  File "C:\Python34\lib\site-packages\django\template\utils.py", line 101, in __getitem__
    engine = engine_cls(params)
  File "C:\Python34\lib\site-packages\django\template\backends\django.py", line 24, in __init__
    self.engine = Engine(self.dirs, self.app_dirs, **options)
TypeError: __init__() got an unexpected keyword argument 'TEMPLATE_DEBUG'
ERROR 2015-08-29 14:34:48,848 Internal Server Error: /index/
Traceback (most recent call last):
  File "C:\Python34\lib\site-packages\django\template\utils.py", line 86, in __getitem__
    return self._engines[alias]
KeyError: 'django'

During handling of the above exception, another exception occurred:

Traceback (most recent call last):
  File "C:\Python34\lib\site-packages\django\core\handlers\base.py", line 132, in get_response
    response = wrapped_callback(request, *callback_args, **callback_kwargs)
  File "C:\Users\Timot\Documents\GitHub\EasyA_Web\index\views.py", line 5, in index
    return render(request, 'index.html')
  File "C:\Python34\lib\site-packages\django\shortcuts.py", line 67, in render
    template_name, context, request=request, using=using)
  File "C:\Python34\lib\site-packages\django\template\loader.py", line 98, in render_to_string
    template = get_template(template_name, using=using)
  File "C:\Python34\lib\site-packages\django\template\loader.py", line 29, in get_template
    engines = _engine_list(using)
  File "C:\Python34\lib\site-packages\django\template\loader.py", line 143, in _engine_list
    return engines.all() if using is None else [engines[using]]
  File "C:\Python34\lib\site-packages\django\template\utils.py", line 110, in all
    return [self[alias] for alias in self]
  File "C:\Python34\lib\site-packages\django\template\utils.py", line 110, in <listcomp>
    return [self[alias] for alias in self]
  File "C:\Python34\lib\site-packages\django\template\utils.py", line 101, in __getitem__
    engine = engine_cls(params)
  File "C:\Python34\lib\site-packages\django\template\backends\django.py", line 24, in __init__
    self.engine = Engine(self.dirs, self.app_dirs, **options)
TypeError: __init__() got an unexpected keyword argument 'TEMPLATE_DEBUG'
ERROR 2015-08-29 14:35:18,475 Internal Server Error: /index/
Traceback (most recent call last):
  File "C:\Python34\lib\site-packages\django\core\handlers\base.py", line 132, in get_response
    response = wrapped_callback(request, *callback_args, **callback_kwargs)
  File "C:\Users\Timot\Documents\GitHub\EasyA_Web\index\views.py", line 5, in index
    return render(request, 'index.html')
  File "C:\Python34\lib\site-packages\django\shortcuts.py", line 67, in render
    template_name, context, request=request, using=using)
  File "C:\Python34\lib\site-packages\django\template\loader.py", line 98, in render_to_string
    template = get_template(template_name, using=using)
  File "C:\Python34\lib\site-packages\django\template\loader.py", line 46, in get_template
    raise TemplateDoesNotExist(template_name)
django.template.base.TemplateDoesNotExist: index.html
ERROR 2015-08-29 14:35:18,475 Internal Server Error: /index/
Traceback (most recent call last):
  File "C:\Python34\lib\site-packages\django\core\handlers\base.py", line 132, in get_response
    response = wrapped_callback(request, *callback_args, **callback_kwargs)
  File "C:\Users\Timot\Documents\GitHub\EasyA_Web\index\views.py", line 5, in index
    return render(request, 'index.html')
  File "C:\Python34\lib\site-packages\django\shortcuts.py", line 67, in render
    template_name, context, request=request, using=using)
  File "C:\Python34\lib\site-packages\django\template\loader.py", line 98, in render_to_string
    template = get_template(template_name, using=using)
  File "C:\Python34\lib\site-packages\django\template\loader.py", line 46, in get_template
    raise TemplateDoesNotExist(template_name)
django.template.base.TemplateDoesNotExist: index.html
ERROR 2015-08-29 14:37:02,352 Internal Server Error: /index/
Traceback (most recent call last):
  File "C:\Python34\lib\site-packages\django\core\handlers\base.py", line 132, in get_response
    response = wrapped_callback(request, *callback_args, **callback_kwargs)
  File "C:\Users\Timot\Documents\GitHub\EasyA_Web\index\views.py", line 5, in index
    return render(request, 'index.html')
  File "C:\Python34\lib\site-packages\django\shortcuts.py", line 67, in render
    template_name, context, request=request, using=using)
  File "C:\Python34\lib\site-packages\django\template\loader.py", line 99, in render_to_string
    return template.render(context, request)
  File "C:\Python34\lib\site-packages\django\template\backends\django.py", line 74, in render
    return self.template.render(context)
  File "C:\Python34\lib\site-packages\django\template\base.py", line 209, in render
    return self._render(context)
  File "C:\Python34\lib\site-packages\django\template\base.py", line 201, in _render
    return self.nodelist.render(context)
  File "C:\Python34\lib\site-packages\django\template\base.py", line 903, in render
    bit = self.render_node(node, context)
  File "C:\Python34\lib\site-packages\django\template\debug.py", line 79, in render_node
    return node.render(context)
  File "C:\Python34\lib\site-packages\django\template\loader_tags.py", line 113, in render
    compiled_parent = self.get_parent(context)
  File "C:\Python34\lib\site-packages\django\template\loader_tags.py", line 110, in get_parent
    return context.template.engine.get_template(parent)
  File "C:\Python34\lib\site-packages\django\template\engine.py", line 167, in get_template
    template, origin = self.find_template(template_name, dirs)
  File "C:\Python34\lib\site-packages\django\template\engine.py", line 146, in find_template
    raise TemplateDoesNotExist(name)
django.template.base.TemplateDoesNotExist: base.html
ERROR 2015-08-29 14:37:02,352 Internal Server Error: /index/
Traceback (most recent call last):
  File "C:\Python34\lib\site-packages\django\core\handlers\base.py", line 132, in get_response
    response = wrapped_callback(request, *callback_args, **callback_kwargs)
  File "C:\Users\Timot\Documents\GitHub\EasyA_Web\index\views.py", line 5, in index
    return render(request, 'index.html')
  File "C:\Python34\lib\site-packages\django\shortcuts.py", line 67, in render
    template_name, context, request=request, using=using)
  File "C:\Python34\lib\site-packages\django\template\loader.py", line 99, in render_to_string
    return template.render(context, request)
  File "C:\Python34\lib\site-packages\django\template\backends\django.py", line 74, in render
    return self.template.render(context)
  File "C:\Python34\lib\site-packages\django\template\base.py", line 209, in render
    return self._render(context)
  File "C:\Python34\lib\site-packages\django\template\base.py", line 201, in _render
    return self.nodelist.render(context)
  File "C:\Python34\lib\site-packages\django\template\base.py", line 903, in render
    bit = self.render_node(node, context)
  File "C:\Python34\lib\site-packages\django\template\debug.py", line 79, in render_node
    return node.render(context)
  File "C:\Python34\lib\site-packages\django\template\loader_tags.py", line 113, in render
    compiled_parent = self.get_parent(context)
  File "C:\Python34\lib\site-packages\django\template\loader_tags.py", line 110, in get_parent
    return context.template.engine.get_template(parent)
  File "C:\Python34\lib\site-packages\django\template\engine.py", line 167, in get_template
    template, origin = self.find_template(template_name, dirs)
  File "C:\Python34\lib\site-packages\django\template\engine.py", line 146, in find_template
    raise TemplateDoesNotExist(name)
django.template.base.TemplateDoesNotExist: base.html
ERROR 2015-08-29 14:38:13,431 Internal Server Error: /index/
Traceback (most recent call last):
  File "C:\Python34\lib\site-packages\django\core\handlers\base.py", line 132, in get_response
    response = wrapped_callback(request, *callback_args, **callback_kwargs)
  File "C:\Users\Timot\Documents\GitHub\EasyA_Web\index\views.py", line 5, in index
    return render(request, 'index.html')
  File "C:\Python34\lib\site-packages\django\shortcuts.py", line 67, in render
    template_name, context, request=request, using=using)
  File "C:\Python34\lib\site-packages\django\template\loader.py", line 99, in render_to_string
    return template.render(context, request)
  File "C:\Python34\lib\site-packages\django\template\backends\django.py", line 74, in render
    return self.template.render(context)
  File "C:\Python34\lib\site-packages\django\template\base.py", line 209, in render
    return self._render(context)
  File "C:\Python34\lib\site-packages\django\template\base.py", line 201, in _render
    return self.nodelist.render(context)
  File "C:\Python34\lib\site-packages\django\template\base.py", line 903, in render
    bit = self.render_node(node, context)
  File "C:\Python34\lib\site-packages\django\template\debug.py", line 79, in render_node
    return node.render(context)
  File "C:\Python34\lib\site-packages\django\template\loader_tags.py", line 113, in render
    compiled_parent = self.get_parent(context)
  File "C:\Python34\lib\site-packages\django\template\loader_tags.py", line 110, in get_parent
    return context.template.engine.get_template(parent)
  File "C:\Python34\lib\site-packages\django\template\engine.py", line 167, in get_template
    template, origin = self.find_template(template_name, dirs)
  File "C:\Python34\lib\site-packages\django\template\engine.py", line 146, in find_template
    raise TemplateDoesNotExist(name)
django.template.base.TemplateDoesNotExist: base.html
ERROR 2015-08-29 14:38:13,431 Internal Server Error: /index/
Traceback (most recent call last):
  File "C:\Python34\lib\site-packages\django\core\handlers\base.py", line 132, in get_response
    response = wrapped_callback(request, *callback_args, **callback_kwargs)
  File "C:\Users\Timot\Documents\GitHub\EasyA_Web\index\views.py", line 5, in index
    return render(request, 'index.html')
  File "C:\Python34\lib\site-packages\django\shortcuts.py", line 67, in render
    template_name, context, request=request, using=using)
  File "C:\Python34\lib\site-packages\django\template\loader.py", line 99, in render_to_string
    return template.render(context, request)
  File "C:\Python34\lib\site-packages\django\template\backends\django.py", line 74, in render
    return self.template.render(context)
  File "C:\Python34\lib\site-packages\django\template\base.py", line 209, in render
    return self._render(context)
  File "C:\Python34\lib\site-packages\django\template\base.py", line 201, in _render
    return self.nodelist.render(context)
  File "C:\Python34\lib\site-packages\django\template\base.py", line 903, in render
    bit = self.render_node(node, context)
  File "C:\Python34\lib\site-packages\django\template\debug.py", line 79, in render_node
    return node.render(context)
  File "C:\Python34\lib\site-packages\django\template\loader_tags.py", line 113, in render
    compiled_parent = self.get_parent(context)
  File "C:\Python34\lib\site-packages\django\template\loader_tags.py", line 110, in get_parent
    return context.template.engine.get_template(parent)
  File "C:\Python34\lib\site-packages\django\template\engine.py", line 167, in get_template
    template, origin = self.find_template(template_name, dirs)
  File "C:\Python34\lib\site-packages\django\template\engine.py", line 146, in find_template
    raise TemplateDoesNotExist(name)
django.template.base.TemplateDoesNotExist: base.html
ERROR 2015-08-29 14:39:29,273 Internal Server Error: /index/
Traceback (most recent call last):
  File "C:\Python34\lib\site-packages\django\core\handlers\base.py", line 132, in get_response
    response = wrapped_callback(request, *callback_args, **callback_kwargs)
  File "C:\Users\Timot\Documents\GitHub\EasyA_Web\index\views.py", line 5, in index
    return render(request, 'index.html')
  File "C:\Python34\lib\site-packages\django\shortcuts.py", line 67, in render
    template_name, context, request=request, using=using)
  File "C:\Python34\lib\site-packages\django\template\loader.py", line 99, in render_to_string
    return template.render(context, request)
  File "C:\Python34\lib\site-packages\django\template\backends\django.py", line 74, in render
    return self.template.render(context)
  File "C:\Python34\lib\site-packages\django\template\base.py", line 209, in render
    return self._render(context)
  File "C:\Python34\lib\site-packages\django\template\base.py", line 201, in _render
    return self.nodelist.render(context)
  File "C:\Python34\lib\site-packages\django\template\base.py", line 903, in render
    bit = self.render_node(node, context)
  File "C:\Python34\lib\site-packages\django\template\debug.py", line 79, in render_node
    return node.render(context)
  File "C:\Python34\lib\site-packages\django\template\loader_tags.py", line 113, in render
    compiled_parent = self.get_parent(context)
  File "C:\Python34\lib\site-packages\django\template\loader_tags.py", line 110, in get_parent
    return context.template.engine.get_template(parent)
  File "C:\Python34\lib\site-packages\django\template\engine.py", line 167, in get_template
    template, origin = self.find_template(template_name, dirs)
  File "C:\Python34\lib\site-packages\django\template\engine.py", line 146, in find_template
    raise TemplateDoesNotExist(name)
django.template.base.TemplateDoesNotExist: base.html
ERROR 2015-08-29 14:39:29,273 Internal Server Error: /index/
Traceback (most recent call last):
  File "C:\Python34\lib\site-packages\django\core\handlers\base.py", line 132, in get_response
    response = wrapped_callback(request, *callback_args, **callback_kwargs)
  File "C:\Users\Timot\Documents\GitHub\EasyA_Web\index\views.py", line 5, in index
    return render(request, 'index.html')
  File "C:\Python34\lib\site-packages\django\shortcuts.py", line 67, in render
    template_name, context, request=request, using=using)
  File "C:\Python34\lib\site-packages\django\template\loader.py", line 99, in render_to_string
    return template.render(context, request)
  File "C:\Python34\lib\site-packages\django\template\backends\django.py", line 74, in render
    return self.template.render(context)
  File "C:\Python34\lib\site-packages\django\template\base.py", line 209, in render
    return self._render(context)
  File "C:\Python34\lib\site-packages\django\template\base.py", line 201, in _render
    return self.nodelist.render(context)
  File "C:\Python34\lib\site-packages\django\template\base.py", line 903, in render
    bit = self.render_node(node, context)
  File "C:\Python34\lib\site-packages\django\template\debug.py", line 79, in render_node
    return node.render(context)
  File "C:\Python34\lib\site-packages\django\template\loader_tags.py", line 113, in render
    compiled_parent = self.get_parent(context)
  File "C:\Python34\lib\site-packages\django\template\loader_tags.py", line 110, in get_parent
    return context.template.engine.get_template(parent)
  File "C:\Python34\lib\site-packages\django\template\engine.py", line 167, in get_template
    template, origin = self.find_template(template_name, dirs)
  File "C:\Python34\lib\site-packages\django\template\engine.py", line 146, in find_template
    raise TemplateDoesNotExist(name)
django.template.base.TemplateDoesNotExist: base.html
ERROR 2015-08-29 14:44:12,944 Internal Server Error: /index/
Traceback (most recent call last):
  File "C:\Python34\lib\site-packages\django\core\handlers\base.py", line 132, in get_response
    response = wrapped_callback(request, *callback_args, **callback_kwargs)
  File "C:\Users\Timot\Documents\GitHub\EasyA_Web\index\views.py", line 5, in index
    return render(request, 'index.html')
  File "C:\Python34\lib\site-packages\django\shortcuts.py", line 67, in render
    template_name, context, request=request, using=using)
  File "C:\Python34\lib\site-packages\django\template\loader.py", line 99, in render_to_string
    return template.render(context, request)
  File "C:\Python34\lib\site-packages\django\template\backends\django.py", line 74, in render
    return self.template.render(context)
  File "C:\Python34\lib\site-packages\django\template\base.py", line 209, in render
    return self._render(context)
  File "C:\Python34\lib\site-packages\django\template\base.py", line 201, in _render
    return self.nodelist.render(context)
  File "C:\Python34\lib\site-packages\django\template\base.py", line 903, in render
    bit = self.render_node(node, context)
  File "C:\Python34\lib\site-packages\django\template\debug.py", line 79, in render_node
    return node.render(context)
  File "C:\Python34\lib\site-packages\django\template\loader_tags.py", line 113, in render
    compiled_parent = self.get_parent(context)
  File "C:\Python34\lib\site-packages\django\template\loader_tags.py", line 110, in get_parent
    return context.template.engine.get_template(parent)
  File "C:\Python34\lib\site-packages\django\template\engine.py", line 167, in get_template
    template, origin = self.find_template(template_name, dirs)
  File "C:\Python34\lib\site-packages\django\template\engine.py", line 146, in find_template
    raise TemplateDoesNotExist(name)
django.template.base.TemplateDoesNotExist: base.html
ERROR 2015-08-29 14:44:12,944 Internal Server Error: /index/
Traceback (most recent call last):
  File "C:\Python34\lib\site-packages\django\core\handlers\base.py", line 132, in get_response
    response = wrapped_callback(request, *callback_args, **callback_kwargs)
  File "C:\Users\Timot\Documents\GitHub\EasyA_Web\index\views.py", line 5, in index
    return render(request, 'index.html')
  File "C:\Python34\lib\site-packages\django\shortcuts.py", line 67, in render
    template_name, context, request=request, using=using)
  File "C:\Python34\lib\site-packages\django\template\loader.py", line 99, in render_to_string
    return template.render(context, request)
  File "C:\Python34\lib\site-packages\django\template\backends\django.py", line 74, in render
    return self.template.render(context)
  File "C:\Python34\lib\site-packages\django\template\base.py", line 209, in render
    return self._render(context)
  File "C:\Python34\lib\site-packages\django\template\base.py", line 201, in _render
    return self.nodelist.render(context)
  File "C:\Python34\lib\site-packages\django\template\base.py", line 903, in render
    bit = self.render_node(node, context)
  File "C:\Python34\lib\site-packages\django\template\debug.py", line 79, in render_node
    return node.render(context)
  File "C:\Python34\lib\site-packages\django\template\loader_tags.py", line 113, in render
    compiled_parent = self.get_parent(context)
  File "C:\Python34\lib\site-packages\django\template\loader_tags.py", line 110, in get_parent
    return context.template.engine.get_template(parent)
  File "C:\Python34\lib\site-packages\django\template\engine.py", line 167, in get_template
    template, origin = self.find_template(template_name, dirs)
  File "C:\Python34\lib\site-packages\django\template\engine.py", line 146, in find_template
    raise TemplateDoesNotExist(name)
django.template.base.TemplateDoesNotExist: base.html
ERROR 2015-08-29 14:45:21,466 Internal Server Error: /index/
Traceback (most recent call last):
  File "C:\Python34\lib\site-packages\django\core\handlers\base.py", line 132, in get_response
    response = wrapped_callback(request, *callback_args, **callback_kwargs)
  File "C:\Users\Timot\Documents\GitHub\EasyA_Web\index\views.py", line 5, in index
    return render(request, 'index.html')
  File "C:\Python34\lib\site-packages\django\shortcuts.py", line 67, in render
    template_name, context, request=request, using=using)
  File "C:\Python34\lib\site-packages\django\template\loader.py", line 99, in render_to_string
    return template.render(context, request)
  File "C:\Python34\lib\site-packages\django\template\backends\django.py", line 74, in render
    return self.template.render(context)
  File "C:\Python34\lib\site-packages\django\template\base.py", line 209, in render
    return self._render(context)
  File "C:\Python34\lib\site-packages\django\template\base.py", line 201, in _render
    return self.nodelist.render(context)
  File "C:\Python34\lib\site-packages\django\template\base.py", line 903, in render
    bit = self.render_node(node, context)
  File "C:\Python34\lib\site-packages\django\template\debug.py", line 79, in render_node
    return node.render(context)
  File "C:\Python34\lib\site-packages\django\template\loader_tags.py", line 113, in render
    compiled_parent = self.get_parent(context)
  File "C:\Python34\lib\site-packages\django\template\loader_tags.py", line 110, in get_parent
    return context.template.engine.get_template(parent)
  File "C:\Python34\lib\site-packages\django\template\engine.py", line 167, in get_template
    template, origin = self.find_template(template_name, dirs)
  File "C:\Python34\lib\site-packages\django\template\engine.py", line 146, in find_template
    raise TemplateDoesNotExist(name)
django.template.base.TemplateDoesNotExist: base.html
ERROR 2015-08-29 14:45:21,466 Internal Server Error: /index/
Traceback (most recent call last):
  File "C:\Python34\lib\site-packages\django\core\handlers\base.py", line 132, in get_response
    response = wrapped_callback(request, *callback_args, **callback_kwargs)
  File "C:\Users\Timot\Documents\GitHub\EasyA_Web\index\views.py", line 5, in index
    return render(request, 'index.html')
  File "C:\Python34\lib\site-packages\django\shortcuts.py", line 67, in render
    template_name, context, request=request, using=using)
  File "C:\Python34\lib\site-packages\django\template\loader.py", line 99, in render_to_string
    return template.render(context, request)
  File "C:\Python34\lib\site-packages\django\template\backends\django.py", line 74, in render
    return self.template.render(context)
  File "C:\Python34\lib\site-packages\django\template\base.py", line 209, in render
    return self._render(context)
  File "C:\Python34\lib\site-packages\django\template\base.py", line 201, in _render
    return self.nodelist.render(context)
  File "C:\Python34\lib\site-packages\django\template\base.py", line 903, in render
    bit = self.render_node(node, context)
  File "C:\Python34\lib\site-packages\django\template\debug.py", line 79, in render_node
    return node.render(context)
  File "C:\Python34\lib\site-packages\django\template\loader_tags.py", line 113, in render
    compiled_parent = self.get_parent(context)
  File "C:\Python34\lib\site-packages\django\template\loader_tags.py", line 110, in get_parent
    return context.template.engine.get_template(parent)
  File "C:\Python34\lib\site-packages\django\template\engine.py", line 167, in get_template
    template, origin = self.find_template(template_name, dirs)
  File "C:\Python34\lib\site-packages\django\template\engine.py", line 146, in find_template
    raise TemplateDoesNotExist(name)
django.template.base.TemplateDoesNotExist: base.html
ERROR 2015-08-29 14:46:12,728 Internal Server Error: /index/
Traceback (most recent call last):
  File "C:\Python34\lib\site-packages\django\core\handlers\base.py", line 132, in get_response
    response = wrapped_callback(request, *callback_args, **callback_kwargs)
  File "C:\Users\Timot\Documents\GitHub\EasyA_Web\index\views.py", line 5, in index
    return render(request, 'index.html')
  File "C:\Python34\lib\site-packages\django\shortcuts.py", line 67, in render
    template_name, context, request=request, using=using)
  File "C:\Python34\lib\site-packages\django\template\loader.py", line 99, in render_to_string
    return template.render(context, request)
  File "C:\Python34\lib\site-packages\django\template\backends\django.py", line 74, in render
    return self.template.render(context)
  File "C:\Python34\lib\site-packages\django\template\base.py", line 209, in render
    return self._render(context)
  File "C:\Python34\lib\site-packages\django\template\base.py", line 201, in _render
    return self.nodelist.render(context)
  File "C:\Python34\lib\site-packages\django\template\base.py", line 903, in render
    bit = self.render_node(node, context)
  File "C:\Python34\lib\site-packages\django\template\debug.py", line 79, in render_node
    return node.render(context)
  File "C:\Python34\lib\site-packages\django\template\loader_tags.py", line 113, in render
    compiled_parent = self.get_parent(context)
  File "C:\Python34\lib\site-packages\django\template\loader_tags.py", line 110, in get_parent
    return context.template.engine.get_template(parent)
  File "C:\Python34\lib\site-packages\django\template\engine.py", line 167, in get_template
    template, origin = self.find_template(template_name, dirs)
  File "C:\Python34\lib\site-packages\django\template\engine.py", line 146, in find_template
    raise TemplateDoesNotExist(name)
django.template.base.TemplateDoesNotExist: base.html
ERROR 2015-08-29 14:46:12,728 Internal Server Error: /index/
Traceback (most recent call last):
  File "C:\Python34\lib\site-packages\django\core\handlers\base.py", line 132, in get_response
    response = wrapped_callback(request, *callback_args, **callback_kwargs)
  File "C:\Users\Timot\Documents\GitHub\EasyA_Web\index\views.py", line 5, in index
    return render(request, 'index.html')
  File "C:\Python34\lib\site-packages\django\shortcuts.py", line 67, in render
    template_name, context, request=request, using=using)
  File "C:\Python34\lib\site-packages\django\template\loader.py", line 99, in render_to_string
    return template.render(context, request)
  File "C:\Python34\lib\site-packages\django\template\backends\django.py", line 74, in render
    return self.template.render(context)
  File "C:\Python34\lib\site-packages\django\template\base.py", line 209, in render
    return self._render(context)
  File "C:\Python34\lib\site-packages\django\template\base.py", line 201, in _render
    return self.nodelist.render(context)
  File "C:\Python34\lib\site-packages\django\template\base.py", line 903, in render
    bit = self.render_node(node, context)
  File "C:\Python34\lib\site-packages\django\template\debug.py", line 79, in render_node
    return node.render(context)
  File "C:\Python34\lib\site-packages\django\template\loader_tags.py", line 113, in render
    compiled_parent = self.get_parent(context)
  File "C:\Python34\lib\site-packages\django\template\loader_tags.py", line 110, in get_parent
    return context.template.engine.get_template(parent)
  File "C:\Python34\lib\site-packages\django\template\engine.py", line 167, in get_template
    template, origin = self.find_template(template_name, dirs)
  File "C:\Python34\lib\site-packages\django\template\engine.py", line 146, in find_template
    raise TemplateDoesNotExist(name)
django.template.base.TemplateDoesNotExist: base.html
ERROR 2015-08-29 14:50:19,156 Internal Server Error: /index/
Traceback (most recent call last):
  File "C:\Python34\lib\site-packages\django\core\handlers\base.py", line 132, in get_response
    response = wrapped_callback(request, *callback_args, **callback_kwargs)
  File "C:\Users\Timot\Documents\GitHub\EasyA_Web\index\views.py", line 5, in index
    return render(request, 'index.html')
  File "C:\Python34\lib\site-packages\django\shortcuts.py", line 67, in render
    template_name, context, request=request, using=using)
  File "C:\Python34\lib\site-packages\django\template\loader.py", line 98, in render_to_string
    template = get_template(template_name, using=using)
  File "C:\Python34\lib\site-packages\django\template\loader.py", line 46, in get_template
    raise TemplateDoesNotExist(template_name)
django.template.base.TemplateDoesNotExist: index.html
ERROR 2015-08-29 14:50:19,156 Internal Server Error: /index/
Traceback (most recent call last):
  File "C:\Python34\lib\site-packages\django\core\handlers\base.py", line 132, in get_response
    response = wrapped_callback(request, *callback_args, **callback_kwargs)
  File "C:\Users\Timot\Documents\GitHub\EasyA_Web\index\views.py", line 5, in index
    return render(request, 'index.html')
  File "C:\Python34\lib\site-packages\django\shortcuts.py", line 67, in render
    template_name, context, request=request, using=using)
  File "C:\Python34\lib\site-packages\django\template\loader.py", line 98, in render_to_string
    template = get_template(template_name, using=using)
  File "C:\Python34\lib\site-packages\django\template\loader.py", line 46, in get_template
    raise TemplateDoesNotExist(template_name)
django.template.base.TemplateDoesNotExist: index.html
ERROR 2015-08-29 14:50:40,026 Internal Server Error: /index/
Traceback (most recent call last):
  File "C:\Python34\lib\site-packages\django\core\handlers\base.py", line 132, in get_response
    response = wrapped_callback(request, *callback_args, **callback_kwargs)
  File "C:\Users\Timot\Documents\GitHub\EasyA_Web\index\views.py", line 5, in index
    return render(request, 'index.html')
  File "C:\Python34\lib\site-packages\django\shortcuts.py", line 67, in render
    template_name, context, request=request, using=using)
  File "C:\Python34\lib\site-packages\django\template\loader.py", line 99, in render_to_string
    return template.render(context, request)
  File "C:\Python34\lib\site-packages\django\template\backends\django.py", line 74, in render
    return self.template.render(context)
  File "C:\Python34\lib\site-packages\django\template\base.py", line 209, in render
    return self._render(context)
  File "C:\Python34\lib\site-packages\django\template\base.py", line 201, in _render
    return self.nodelist.render(context)
  File "C:\Python34\lib\site-packages\django\template\base.py", line 903, in render
    bit = self.render_node(node, context)
  File "C:\Python34\lib\site-packages\django\template\debug.py", line 79, in render_node
    return node.render(context)
  File "C:\Python34\lib\site-packages\django\template\loader_tags.py", line 113, in render
    compiled_parent = self.get_parent(context)
  File "C:\Python34\lib\site-packages\django\template\loader_tags.py", line 110, in get_parent
    return context.template.engine.get_template(parent)
  File "C:\Python34\lib\site-packages\django\template\engine.py", line 167, in get_template
    template, origin = self.find_template(template_name, dirs)
  File "C:\Python34\lib\site-packages\django\template\engine.py", line 146, in find_template
    raise TemplateDoesNotExist(name)
django.template.base.TemplateDoesNotExist: base.html
ERROR 2015-08-29 14:50:40,026 Internal Server Error: /index/
Traceback (most recent call last):
  File "C:\Python34\lib\site-packages\django\core\handlers\base.py", line 132, in get_response
    response = wrapped_callback(request, *callback_args, **callback_kwargs)
  File "C:\Users\Timot\Documents\GitHub\EasyA_Web\index\views.py", line 5, in index
    return render(request, 'index.html')
  File "C:\Python34\lib\site-packages\django\shortcuts.py", line 67, in render
    template_name, context, request=request, using=using)
  File "C:\Python34\lib\site-packages\django\template\loader.py", line 99, in render_to_string
    return template.render(context, request)
  File "C:\Python34\lib\site-packages\django\template\backends\django.py", line 74, in render
    return self.template.render(context)
  File "C:\Python34\lib\site-packages\django\template\base.py", line 209, in render
    return self._render(context)
  File "C:\Python34\lib\site-packages\django\template\base.py", line 201, in _render
    return self.nodelist.render(context)
  File "C:\Python34\lib\site-packages\django\template\base.py", line 903, in render
    bit = self.render_node(node, context)
  File "C:\Python34\lib\site-packages\django\template\debug.py", line 79, in render_node
    return node.render(context)
  File "C:\Python34\lib\site-packages\django\template\loader_tags.py", line 113, in render
    compiled_parent = self.get_parent(context)
  File "C:\Python34\lib\site-packages\django\template\loader_tags.py", line 110, in get_parent
    return context.template.engine.get_template(parent)
  File "C:\Python34\lib\site-packages\django\template\engine.py", line 167, in get_template
    template, origin = self.find_template(template_name, dirs)
  File "C:\Python34\lib\site-packages\django\template\engine.py", line 146, in find_template
    raise TemplateDoesNotExist(name)
django.template.base.TemplateDoesNotExist: base.html
ERROR 2015-08-29 14:50:51,679 Internal Server Error: /index/
Traceback (most recent call last):
  File "C:\Python34\lib\site-packages\django\core\handlers\base.py", line 132, in get_response
    response = wrapped_callback(request, *callback_args, **callback_kwargs)
  File "C:\Users\Timot\Documents\GitHub\EasyA_Web\index\views.py", line 5, in index
    return render(request, 'index.html')
  File "C:\Python34\lib\site-packages\django\shortcuts.py", line 67, in render
    template_name, context, request=request, using=using)
  File "C:\Python34\lib\site-packages\django\template\loader.py", line 99, in render_to_string
    return template.render(context, request)
  File "C:\Python34\lib\site-packages\django\template\backends\django.py", line 74, in render
    return self.template.render(context)
  File "C:\Python34\lib\site-packages\django\template\base.py", line 209, in render
    return self._render(context)
  File "C:\Python34\lib\site-packages\django\template\base.py", line 201, in _render
    return self.nodelist.render(context)
  File "C:\Python34\lib\site-packages\django\template\base.py", line 903, in render
    bit = self.render_node(node, context)
  File "C:\Python34\lib\site-packages\django\template\debug.py", line 79, in render_node
    return node.render(context)
  File "C:\Python34\lib\site-packages\django\template\loader_tags.py", line 113, in render
    compiled_parent = self.get_parent(context)
  File "C:\Python34\lib\site-packages\django\template\loader_tags.py", line 110, in get_parent
    return context.template.engine.get_template(parent)
  File "C:\Python34\lib\site-packages\django\template\engine.py", line 167, in get_template
    template, origin = self.find_template(template_name, dirs)
  File "C:\Python34\lib\site-packages\django\template\engine.py", line 146, in find_template
    raise TemplateDoesNotExist(name)
django.template.base.TemplateDoesNotExist: base.html
ERROR 2015-08-29 14:50:51,679 Internal Server Error: /index/
Traceback (most recent call last):
  File "C:\Python34\lib\site-packages\django\core\handlers\base.py", line 132, in get_response
    response = wrapped_callback(request, *callback_args, **callback_kwargs)
  File "C:\Users\Timot\Documents\GitHub\EasyA_Web\index\views.py", line 5, in index
    return render(request, 'index.html')
  File "C:\Python34\lib\site-packages\django\shortcuts.py", line 67, in render
    template_name, context, request=request, using=using)
  File "C:\Python34\lib\site-packages\django\template\loader.py", line 99, in render_to_string
    return template.render(context, request)
  File "C:\Python34\lib\site-packages\django\template\backends\django.py", line 74, in render
    return self.template.render(context)
  File "C:\Python34\lib\site-packages\django\template\base.py", line 209, in render
    return self._render(context)
  File "C:\Python34\lib\site-packages\django\template\base.py", line 201, in _render
    return self.nodelist.render(context)
  File "C:\Python34\lib\site-packages\django\template\base.py", line 903, in render
    bit = self.render_node(node, context)
  File "C:\Python34\lib\site-packages\django\template\debug.py", line 79, in render_node
    return node.render(context)
  File "C:\Python34\lib\site-packages\django\template\loader_tags.py", line 113, in render
    compiled_parent = self.get_parent(context)
  File "C:\Python34\lib\site-packages\django\template\loader_tags.py", line 110, in get_parent
    return context.template.engine.get_template(parent)
  File "C:\Python34\lib\site-packages\django\template\engine.py", line 167, in get_template
    template, origin = self.find_template(template_name, dirs)
  File "C:\Python34\lib\site-packages\django\template\engine.py", line 146, in find_template
    raise TemplateDoesNotExist(name)
django.template.base.TemplateDoesNotExist: base.html
ERROR 2015-08-29 14:51:14,302 Internal Server Error: /index/
Traceback (most recent call last):
  File "C:\Python34\lib\site-packages\django\core\handlers\base.py", line 132, in get_response
    response = wrapped_callback(request, *callback_args, **callback_kwargs)
  File "C:\Users\Timot\Documents\GitHub\EasyA_Web\index\views.py", line 5, in index
    return render(request, 'index.html')
  File "C:\Python34\lib\site-packages\django\shortcuts.py", line 67, in render
    template_name, context, request=request, using=using)
  File "C:\Python34\lib\site-packages\django\template\loader.py", line 99, in render_to_string
    return template.render(context, request)
  File "C:\Python34\lib\site-packages\django\template\backends\django.py", line 74, in render
    return self.template.render(context)
  File "C:\Python34\lib\site-packages\django\template\base.py", line 209, in render
    return self._render(context)
  File "C:\Python34\lib\site-packages\django\template\base.py", line 201, in _render
    return self.nodelist.render(context)
  File "C:\Python34\lib\site-packages\django\template\base.py", line 903, in render
    bit = self.render_node(node, context)
  File "C:\Python34\lib\site-packages\django\template\debug.py", line 79, in render_node
    return node.render(context)
  File "C:\Python34\lib\site-packages\django\template\loader_tags.py", line 113, in render
    compiled_parent = self.get_parent(context)
  File "C:\Python34\lib\site-packages\django\template\loader_tags.py", line 110, in get_parent
    return context.template.engine.get_template(parent)
  File "C:\Python34\lib\site-packages\django\template\engine.py", line 167, in get_template
    template, origin = self.find_template(template_name, dirs)
  File "C:\Python34\lib\site-packages\django\template\engine.py", line 146, in find_template
    raise TemplateDoesNotExist(name)
django.template.base.TemplateDoesNotExist: base.html
ERROR 2015-08-29 14:51:14,302 Internal Server Error: /index/
Traceback (most recent call last):
  File "C:\Python34\lib\site-packages\django\core\handlers\base.py", line 132, in get_response
    response = wrapped_callback(request, *callback_args, **callback_kwargs)
  File "C:\Users\Timot\Documents\GitHub\EasyA_Web\index\views.py", line 5, in index
    return render(request, 'index.html')
  File "C:\Python34\lib\site-packages\django\shortcuts.py", line 67, in render
    template_name, context, request=request, using=using)
  File "C:\Python34\lib\site-packages\django\template\loader.py", line 99, in render_to_string
    return template.render(context, request)
  File "C:\Python34\lib\site-packages\django\template\backends\django.py", line 74, in render
    return self.template.render(context)
  File "C:\Python34\lib\site-packages\django\template\base.py", line 209, in render
    return self._render(context)
  File "C:\Python34\lib\site-packages\django\template\base.py", line 201, in _render
    return self.nodelist.render(context)
  File "C:\Python34\lib\site-packages\django\template\base.py", line 903, in render
    bit = self.render_node(node, context)
  File "C:\Python34\lib\site-packages\django\template\debug.py", line 79, in render_node
    return node.render(context)
  File "C:\Python34\lib\site-packages\django\template\loader_tags.py", line 113, in render
    compiled_parent = self.get_parent(context)
  File "C:\Python34\lib\site-packages\django\template\loader_tags.py", line 110, in get_parent
    return context.template.engine.get_template(parent)
  File "C:\Python34\lib\site-packages\django\template\engine.py", line 167, in get_template
    template, origin = self.find_template(template_name, dirs)
  File "C:\Python34\lib\site-packages\django\template\engine.py", line 146, in find_template
    raise TemplateDoesNotExist(name)
django.template.base.TemplateDoesNotExist: base.html
ERROR 2015-08-29 14:51:30,589 Internal Server Error: /index/
Traceback (most recent call last):
  File "C:\Python34\lib\site-packages\django\core\handlers\base.py", line 132, in get_response
    response = wrapped_callback(request, *callback_args, **callback_kwargs)
  File "C:\Users\Timot\Documents\GitHub\EasyA_Web\index\views.py", line 5, in index
    return render(request, 'index.html')
  File "C:\Python34\lib\site-packages\django\shortcuts.py", line 67, in render
    template_name, context, request=request, using=using)
  File "C:\Python34\lib\site-packages\django\template\loader.py", line 99, in render_to_string
    return template.render(context, request)
  File "C:\Python34\lib\site-packages\django\template\backends\django.py", line 74, in render
    return self.template.render(context)
  File "C:\Python34\lib\site-packages\django\template\base.py", line 209, in render
    return self._render(context)
  File "C:\Python34\lib\site-packages\django\template\base.py", line 201, in _render
    return self.nodelist.render(context)
  File "C:\Python34\lib\site-packages\django\template\base.py", line 903, in render
    bit = self.render_node(node, context)
  File "C:\Python34\lib\site-packages\django\template\debug.py", line 79, in render_node
    return node.render(context)
  File "C:\Python34\lib\site-packages\django\template\loader_tags.py", line 113, in render
    compiled_parent = self.get_parent(context)
  File "C:\Python34\lib\site-packages\django\template\loader_tags.py", line 110, in get_parent
    return context.template.engine.get_template(parent)
  File "C:\Python34\lib\site-packages\django\template\engine.py", line 167, in get_template
    template, origin = self.find_template(template_name, dirs)
  File "C:\Python34\lib\site-packages\django\template\engine.py", line 146, in find_template
    raise TemplateDoesNotExist(name)
django.template.base.TemplateDoesNotExist: base.html
ERROR 2015-08-29 14:51:30,589 Internal Server Error: /index/
Traceback (most recent call last):
  File "C:\Python34\lib\site-packages\django\core\handlers\base.py", line 132, in get_response
    response = wrapped_callback(request, *callback_args, **callback_kwargs)
  File "C:\Users\Timot\Documents\GitHub\EasyA_Web\index\views.py", line 5, in index
    return render(request, 'index.html')
  File "C:\Python34\lib\site-packages\django\shortcuts.py", line 67, in render
    template_name, context, request=request, using=using)
  File "C:\Python34\lib\site-packages\django\template\loader.py", line 99, in render_to_string
    return template.render(context, request)
  File "C:\Python34\lib\site-packages\django\template\backends\django.py", line 74, in render
    return self.template.render(context)
  File "C:\Python34\lib\site-packages\django\template\base.py", line 209, in render
    return self._render(context)
  File "C:\Python34\lib\site-packages\django\template\base.py", line 201, in _render
    return self.nodelist.render(context)
  File "C:\Python34\lib\site-packages\django\template\base.py", line 903, in render
    bit = self.render_node(node, context)
  File "C:\Python34\lib\site-packages\django\template\debug.py", line 79, in render_node
    return node.render(context)
  File "C:\Python34\lib\site-packages\django\template\loader_tags.py", line 113, in render
    compiled_parent = self.get_parent(context)
  File "C:\Python34\lib\site-packages\django\template\loader_tags.py", line 110, in get_parent
    return context.template.engine.get_template(parent)
  File "C:\Python34\lib\site-packages\django\template\engine.py", line 167, in get_template
    template, origin = self.find_template(template_name, dirs)
  File "C:\Python34\lib\site-packages\django\template\engine.py", line 146, in find_template
    raise TemplateDoesNotExist(name)
django.template.base.TemplateDoesNotExist: base.html
ERROR 2015-08-29 14:51:52,701 Internal Server Error: /index/
Traceback (most recent call last):
  File "C:\Python34\lib\site-packages\django\core\handlers\base.py", line 132, in get_response
    response = wrapped_callback(request, *callback_args, **callback_kwargs)
  File "C:\Users\Timot\Documents\GitHub\EasyA_Web\index\views.py", line 5, in index
    return render(request, 'index.html')
  File "C:\Python34\lib\site-packages\django\shortcuts.py", line 67, in render
    template_name, context, request=request, using=using)
  File "C:\Python34\lib\site-packages\django\template\loader.py", line 99, in render_to_string
    return template.render(context, request)
  File "C:\Python34\lib\site-packages\django\template\backends\django.py", line 74, in render
    return self.template.render(context)
  File "C:\Python34\lib\site-packages\django\template\base.py", line 209, in render
    return self._render(context)
  File "C:\Python34\lib\site-packages\django\template\base.py", line 201, in _render
    return self.nodelist.render(context)
  File "C:\Python34\lib\site-packages\django\template\base.py", line 903, in render
    bit = self.render_node(node, context)
  File "C:\Python34\lib\site-packages\django\template\debug.py", line 79, in render_node
    return node.render(context)
  File "C:\Python34\lib\site-packages\django\template\loader_tags.py", line 113, in render
    compiled_parent = self.get_parent(context)
  File "C:\Python34\lib\site-packages\django\template\loader_tags.py", line 110, in get_parent
    return context.template.engine.get_template(parent)
  File "C:\Python34\lib\site-packages\django\template\engine.py", line 167, in get_template
    template, origin = self.find_template(template_name, dirs)
  File "C:\Python34\lib\site-packages\django\template\engine.py", line 146, in find_template
    raise TemplateDoesNotExist(name)
django.template.base.TemplateDoesNotExist: base.html
ERROR 2015-08-29 14:51:52,701 Internal Server Error: /index/
Traceback (most recent call last):
  File "C:\Python34\lib\site-packages\django\core\handlers\base.py", line 132, in get_response
    response = wrapped_callback(request, *callback_args, **callback_kwargs)
  File "C:\Users\Timot\Documents\GitHub\EasyA_Web\index\views.py", line 5, in index
    return render(request, 'index.html')
  File "C:\Python34\lib\site-packages\django\shortcuts.py", line 67, in render
    template_name, context, request=request, using=using)
  File "C:\Python34\lib\site-packages\django\template\loader.py", line 99, in render_to_string
    return template.render(context, request)
  File "C:\Python34\lib\site-packages\django\template\backends\django.py", line 74, in render
    return self.template.render(context)
  File "C:\Python34\lib\site-packages\django\template\base.py", line 209, in render
    return self._render(context)
  File "C:\Python34\lib\site-packages\django\template\base.py", line 201, in _render
    return self.nodelist.render(context)
  File "C:\Python34\lib\site-packages\django\template\base.py", line 903, in render
    bit = self.render_node(node, context)
  File "C:\Python34\lib\site-packages\django\template\debug.py", line 79, in render_node
    return node.render(context)
  File "C:\Python34\lib\site-packages\django\template\loader_tags.py", line 113, in render
    compiled_parent = self.get_parent(context)
  File "C:\Python34\lib\site-packages\django\template\loader_tags.py", line 110, in get_parent
    return context.template.engine.get_template(parent)
  File "C:\Python34\lib\site-packages\django\template\engine.py", line 167, in get_template
    template, origin = self.find_template(template_name, dirs)
  File "C:\Python34\lib\site-packages\django\template\engine.py", line 146, in find_template
    raise TemplateDoesNotExist(name)
django.template.base.TemplateDoesNotExist: base.html
ERROR 2015-08-29 14:52:17,690 Internal Server Error: /index/
Traceback (most recent call last):
  File "C:\Python34\lib\site-packages\django\core\handlers\base.py", line 132, in get_response
    response = wrapped_callback(request, *callback_args, **callback_kwargs)
  File "C:\Users\Timot\Documents\GitHub\EasyA_Web\index\views.py", line 5, in index
    return render(request, 'index.html')
  File "C:\Python34\lib\site-packages\django\shortcuts.py", line 67, in render
    template_name, context, request=request, using=using)
  File "C:\Python34\lib\site-packages\django\template\loader.py", line 99, in render_to_string
    return template.render(context, request)
  File "C:\Python34\lib\site-packages\django\template\backends\django.py", line 74, in render
    return self.template.render(context)
  File "C:\Python34\lib\site-packages\django\template\base.py", line 209, in render
    return self._render(context)
  File "C:\Python34\lib\site-packages\django\template\base.py", line 201, in _render
    return self.nodelist.render(context)
  File "C:\Python34\lib\site-packages\django\template\base.py", line 903, in render
    bit = self.render_node(node, context)
  File "C:\Python34\lib\site-packages\django\template\debug.py", line 79, in render_node
    return node.render(context)
  File "C:\Python34\lib\site-packages\django\template\loader_tags.py", line 113, in render
    compiled_parent = self.get_parent(context)
  File "C:\Python34\lib\site-packages\django\template\loader_tags.py", line 110, in get_parent
    return context.template.engine.get_template(parent)
  File "C:\Python34\lib\site-packages\django\template\engine.py", line 167, in get_template
    template, origin = self.find_template(template_name, dirs)
  File "C:\Python34\lib\site-packages\django\template\engine.py", line 146, in find_template
    raise TemplateDoesNotExist(name)
django.template.base.TemplateDoesNotExist: base.html
ERROR 2015-08-29 14:52:17,690 Internal Server Error: /index/
Traceback (most recent call last):
  File "C:\Python34\lib\site-packages\django\core\handlers\base.py", line 132, in get_response
    response = wrapped_callback(request, *callback_args, **callback_kwargs)
  File "C:\Users\Timot\Documents\GitHub\EasyA_Web\index\views.py", line 5, in index
    return render(request, 'index.html')
  File "C:\Python34\lib\site-packages\django\shortcuts.py", line 67, in render
    template_name, context, request=request, using=using)
  File "C:\Python34\lib\site-packages\django\template\loader.py", line 99, in render_to_string
    return template.render(context, request)
  File "C:\Python34\lib\site-packages\django\template\backends\django.py", line 74, in render
    return self.template.render(context)
  File "C:\Python34\lib\site-packages\django\template\base.py", line 209, in render
    return self._render(context)
  File "C:\Python34\lib\site-packages\django\template\base.py", line 201, in _render
    return self.nodelist.render(context)
  File "C:\Python34\lib\site-packages\django\template\base.py", line 903, in render
    bit = self.render_node(node, context)
  File "C:\Python34\lib\site-packages\django\template\debug.py", line 79, in render_node
    return node.render(context)
  File "C:\Python34\lib\site-packages\django\template\loader_tags.py", line 113, in render
    compiled_parent = self.get_parent(context)
  File "C:\Python34\lib\site-packages\django\template\loader_tags.py", line 110, in get_parent
    return context.template.engine.get_template(parent)
  File "C:\Python34\lib\site-packages\django\template\engine.py", line 167, in get_template
    template, origin = self.find_template(template_name, dirs)
  File "C:\Python34\lib\site-packages\django\template\engine.py", line 146, in find_template
    raise TemplateDoesNotExist(name)
django.template.base.TemplateDoesNotExist: base.html
ERROR 2015-08-29 14:52:24,149 Internal Server Error: /index/
Traceback (most recent call last):
  File "C:\Python34\lib\site-packages\django\core\handlers\base.py", line 132, in get_response
    response = wrapped_callback(request, *callback_args, **callback_kwargs)
  File "C:\Users\Timot\Documents\GitHub\EasyA_Web\index\views.py", line 5, in index
    return render(request, 'index.html')
  File "C:\Python34\lib\site-packages\django\shortcuts.py", line 67, in render
    template_name, context, request=request, using=using)
  File "C:\Python34\lib\site-packages\django\template\loader.py", line 99, in render_to_string
    return template.render(context, request)
  File "C:\Python34\lib\site-packages\django\template\backends\django.py", line 74, in render
    return self.template.render(context)
  File "C:\Python34\lib\site-packages\django\template\base.py", line 209, in render
    return self._render(context)
  File "C:\Python34\lib\site-packages\django\template\base.py", line 201, in _render
    return self.nodelist.render(context)
  File "C:\Python34\lib\site-packages\django\template\base.py", line 903, in render
    bit = self.render_node(node, context)
  File "C:\Python34\lib\site-packages\django\template\debug.py", line 79, in render_node
    return node.render(context)
  File "C:\Python34\lib\site-packages\django\template\loader_tags.py", line 113, in render
    compiled_parent = self.get_parent(context)
  File "C:\Python34\lib\site-packages\django\template\loader_tags.py", line 110, in get_parent
    return context.template.engine.get_template(parent)
  File "C:\Python34\lib\site-packages\django\template\engine.py", line 167, in get_template
    template, origin = self.find_template(template_name, dirs)
  File "C:\Python34\lib\site-packages\django\template\engine.py", line 146, in find_template
    raise TemplateDoesNotExist(name)
django.template.base.TemplateDoesNotExist: base.html
ERROR 2015-08-29 14:52:24,149 Internal Server Error: /index/
Traceback (most recent call last):
  File "C:\Python34\lib\site-packages\django\core\handlers\base.py", line 132, in get_response
    response = wrapped_callback(request, *callback_args, **callback_kwargs)
  File "C:\Users\Timot\Documents\GitHub\EasyA_Web\index\views.py", line 5, in index
    return render(request, 'index.html')
  File "C:\Python34\lib\site-packages\django\shortcuts.py", line 67, in render
    template_name, context, request=request, using=using)
  File "C:\Python34\lib\site-packages\django\template\loader.py", line 99, in render_to_string
    return template.render(context, request)
  File "C:\Python34\lib\site-packages\django\template\backends\django.py", line 74, in render
    return self.template.render(context)
  File "C:\Python34\lib\site-packages\django\template\base.py", line 209, in render
    return self._render(context)
  File "C:\Python34\lib\site-packages\django\template\base.py", line 201, in _render
    return self.nodelist.render(context)
  File "C:\Python34\lib\site-packages\django\template\base.py", line 903, in render
    bit = self.render_node(node, context)
  File "C:\Python34\lib\site-packages\django\template\debug.py", line 79, in render_node
    return node.render(context)
  File "C:\Python34\lib\site-packages\django\template\loader_tags.py", line 113, in render
    compiled_parent = self.get_parent(context)
  File "C:\Python34\lib\site-packages\django\template\loader_tags.py", line 110, in get_parent
    return context.template.engine.get_template(parent)
  File "C:\Python34\lib\site-packages\django\template\engine.py", line 167, in get_template
    template, origin = self.find_template(template_name, dirs)
  File "C:\Python34\lib\site-packages\django\template\engine.py", line 146, in find_template
    raise TemplateDoesNotExist(name)
django.template.base.TemplateDoesNotExist: base.html
WARNING 2015-08-29 14:52:24,380 Not Found: /favicon.ico
WARNING 2015-08-29 14:52:24,380 Not Found: /favicon.ico
WARNING 2015-08-29 15:03:51,348 Not Found: /index/...
WARNING 2015-08-29 15:03:51,348 Not Found: /index/...
ERROR 2015-08-29 15:07:08,812 Internal Server Error: /index/
Traceback (most recent call last):
  File "C:\Python34\lib\site-packages\django\template\base.py", line 337, in parse
    compile_func = self.tags[command]
KeyError: 'static'

During handling of the above exception, another exception occurred:

Traceback (most recent call last):
  File "C:\Python34\lib\site-packages\django\core\handlers\base.py", line 132, in get_response
    response = wrapped_callback(request, *callback_args, **callback_kwargs)
  File "C:\Users\Timot\Documents\GitHub\EasyA_Web\index\views.py", line 5, in index
    return render(request, 'index.html')
  File "C:\Python34\lib\site-packages\django\shortcuts.py", line 67, in render
    template_name, context, request=request, using=using)
  File "C:\Python34\lib\site-packages\django\template\loader.py", line 98, in render_to_string
    template = get_template(template_name, using=using)
  File "C:\Python34\lib\site-packages\django\template\loader.py", line 35, in get_template
    return engine.get_template(template_name, dirs)
  File "C:\Python34\lib\site-packages\django\template\backends\django.py", line 30, in get_template
    return Template(self.engine.get_template(template_name, dirs))
  File "C:\Python34\lib\site-packages\django\template\engine.py", line 167, in get_template
    template, origin = self.find_template(template_name, dirs)
  File "C:\Python34\lib\site-packages\django\template\engine.py", line 141, in find_template
    source, display_name = loader(name, dirs)
  File "C:\Python34\lib\site-packages\django\template\loaders\base.py", line 13, in __call__
    return self.load_template(template_name, template_dirs)
  File "C:\Python34\lib\site-packages\django\template\loaders\base.py", line 23, in load_template
    template = Template(source, origin, template_name, self.engine)
  File "C:\Python34\lib\site-packages\django\template\base.py", line 190, in __init__
    self.nodelist = engine.compile_string(template_string, origin)
  File "C:\Python34\lib\site-packages\django\template\engine.py", line 261, in compile_string
    return parser.parse()
  File "C:\Python34\lib\site-packages\django\template\base.py", line 341, in parse
    compiled_result = compile_func(self, token)
  File "C:\Python34\lib\site-packages\django\template\loader_tags.py", line 210, in do_extends
    nodelist = parser.parse()
  File "C:\Python34\lib\site-packages\django\template\base.py", line 341, in parse
    compiled_result = compile_func(self, token)
  File "C:\Python34\lib\site-packages\django\template\loader_tags.py", line 184, in do_block
    nodelist = parser.parse(('endblock',))
  File "C:\Python34\lib\site-packages\django\template\base.py", line 339, in parse
    self.invalid_block_tag(token, command, parse_until)
  File "C:\Python34\lib\site-packages\django\template\base.py", line 394, in invalid_block_tag
    (command, get_text_list(["'%s'" % p for p in parse_until])))
django.template.base.TemplateSyntaxError: Invalid block tag: 'static', expected 'endblock'
ERROR 2015-08-29 15:07:08,812 Internal Server Error: /index/
Traceback (most recent call last):
  File "C:\Python34\lib\site-packages\django\template\base.py", line 337, in parse
    compile_func = self.tags[command]
KeyError: 'static'

During handling of the above exception, another exception occurred:

Traceback (most recent call last):
  File "C:\Python34\lib\site-packages\django\core\handlers\base.py", line 132, in get_response
    response = wrapped_callback(request, *callback_args, **callback_kwargs)
  File "C:\Users\Timot\Documents\GitHub\EasyA_Web\index\views.py", line 5, in index
    return render(request, 'index.html')
  File "C:\Python34\lib\site-packages\django\shortcuts.py", line 67, in render
    template_name, context, request=request, using=using)
  File "C:\Python34\lib\site-packages\django\template\loader.py", line 98, in render_to_string
    template = get_template(template_name, using=using)
  File "C:\Python34\lib\site-packages\django\template\loader.py", line 35, in get_template
    return engine.get_template(template_name, dirs)
  File "C:\Python34\lib\site-packages\django\template\backends\django.py", line 30, in get_template
    return Template(self.engine.get_template(template_name, dirs))
  File "C:\Python34\lib\site-packages\django\template\engine.py", line 167, in get_template
    template, origin = self.find_template(template_name, dirs)
  File "C:\Python34\lib\site-packages\django\template\engine.py", line 141, in find_template
    source, display_name = loader(name, dirs)
  File "C:\Python34\lib\site-packages\django\template\loaders\base.py", line 13, in __call__
    return self.load_template(template_name, template_dirs)
  File "C:\Python34\lib\site-packages\django\template\loaders\base.py", line 23, in load_template
    template = Template(source, origin, template_name, self.engine)
  File "C:\Python34\lib\site-packages\django\template\base.py", line 190, in __init__
    self.nodelist = engine.compile_string(template_string, origin)
  File "C:\Python34\lib\site-packages\django\template\engine.py", line 261, in compile_string
    return parser.parse()
  File "C:\Python34\lib\site-packages\django\template\base.py", line 341, in parse
    compiled_result = compile_func(self, token)
  File "C:\Python34\lib\site-packages\django\template\loader_tags.py", line 210, in do_extends
    nodelist = parser.parse()
  File "C:\Python34\lib\site-packages\django\template\base.py", line 341, in parse
    compiled_result = compile_func(self, token)
  File "C:\Python34\lib\site-packages\django\template\loader_tags.py", line 184, in do_block
    nodelist = parser.parse(('endblock',))
  File "C:\Python34\lib\site-packages\django\template\base.py", line 339, in parse
    self.invalid_block_tag(token, command, parse_until)
  File "C:\Python34\lib\site-packages\django\template\base.py", line 394, in invalid_block_tag
    (command, get_text_list(["'%s'" % p for p in parse_until])))
django.template.base.TemplateSyntaxError: Invalid block tag: 'static', expected 'endblock'
WARNING 2015-08-31 20:59:27,481 Not Found: /favicon.ico
WARNING 2015-08-31 20:59:49,996 Not Found: /login
WARNING 2015-08-31 21:01:40,288 Not Found: /login
WARNING 2015-08-31 21:01:42,952 Not Found: /login
ERROR 2015-08-31 21:01:48,588 Internal Server Error: /index/login/
Traceback (most recent call last):
  File "C:\Python34\lib\site-packages\django\core\handlers\base.py", line 151, in get_response
    % (callback.__module__, view_name))
ValueError: The view index.views.login didn't return an HttpResponse object. It returned None instead.
ERROR 2015-08-31 21:08:45,393 Internal Server Error: /index/login
Traceback (most recent call last):
  File "C:\Python34\lib\site-packages\django\core\handlers\base.py", line 108, in get_response
    response = middleware_method(request)
  File "C:\Python34\lib\site-packages\django\middleware\common.py", line 84, in process_request
    "settings.") % (new_url[0], new_url[1]))
RuntimeError: You called this URL via POST, but the URL doesn't end in a slash and you have APPEND_SLASH set. Django can't redirect to the slash URL while maintaining POST data. Change your form to point to 127.0.0.1:8080/index/login/ (note the trailing slash), or set APPEND_SLASH=False in your Django settings.
WARNING 2015-08-31 21:08:57,476 Forbidden (CSRF token missing or incorrect.): /index/login/
ERROR 2015-08-31 21:13:32,087 Internal Server Error: /index/login/
Traceback (most recent call last):
  File "C:\Python34\lib\site-packages\django\core\handlers\base.py", line 132, in get_response
    response = wrapped_callback(request, *callback_args, **callback_kwargs)
  File "C:\Python34\lib\site-packages\django\views\decorators\csrf.py", line 58, in wrapped_view
    return view_func(*args, **kwargs)
  File "C:\Users\Timot\Documents\GitHub\EasyA_Web\index\views.py", line 17, in login
    request.session.set("isLoggedIn", True)
AttributeError: 'SessionStore' object has no attribute 'set'
ERROR 2015-08-31 21:14:34,141 Internal Server Error: /index/login/
Traceback (most recent call last):
  File "C:\Python34\lib\site-packages\django\core\handlers\base.py", line 223, in get_response
    response = middleware_method(request, response)
  File "C:\Python34\lib\site-packages\django\contrib\sessions\middleware.py", line 50, in process_response
    request.session.save()
  File "C:\Python34\lib\site-packages\django\contrib\sessions\backends\db.py", line 56, in save
    return self.create()
  File "C:\Python34\lib\site-packages\django\contrib\sessions\backends\db.py", line 37, in create
    self._session_key = self._get_new_session_key()
  File "C:\Python34\lib\site-packages\django\contrib\sessions\backends\base.py", line 155, in _get_new_session_key
    if not self.exists(session_key):
  File "C:\Python34\lib\site-packages\django\contrib\sessions\backends\db.py", line 33, in exists
    return Session.objects.filter(session_key=session_key).exists()
  File "C:\Python34\lib\site-packages\django\db\models\query.py", line 586, in exists
    return self.query.has_results(using=self.db)
  File "C:\Python34\lib\site-packages\django\db\models\sql\query.py", line 484, in has_results
    return compiler.has_results()
  File "C:\Python34\lib\site-packages\django\db\models\sql\compiler.py", line 811, in has_results
    return bool(self.execute_sql(SINGLE))
  File "C:\Python34\lib\site-packages\django\db\models\sql\compiler.py", line 829, in execute_sql
    sql, params = self.as_sql()
  File "C:\Python34\lib\site-packages\django\db\models\sql\compiler.py", line 385, in as_sql
    from_, f_params = self.get_from_clause()
  File "C:\Python34\lib\site-packages\django\db\models\sql\compiler.py", line 617, in get_from_clause
    clause_sql, clause_params = self.compile(from_clause)
  File "C:\Python34\lib\site-packages\django\db\models\sql\compiler.py", line 357, in compile
    sql, params = node.as_sql(self, self.connection)
  File "C:\Python34\lib\site-packages\django\db\models\sql\datastructures.py", line 137, in as_sql
    base_sql = compiler.quote_name_unless_alias(self.table_name)
  File "C:\Python34\lib\site-packages\django\db\models\sql\compiler.py", line 348, in quote_name_unless_alias
    r = self.connection.ops.quote_name(name)
  File "C:\Python34\lib\site-packages\django\db\backends\dummy\base.py", line 21, in complain
    raise ImproperlyConfigured("settings.DATABASES is improperly configured. "
django.core.exceptions.ImproperlyConfigured: settings.DATABASES is improperly configured. Please supply the ENGINE value. Check settings documentation for more details.
ERROR 2015-08-31 21:14:46,318 Internal Server Error: /index/login/
Traceback (most recent call last):
  File "C:\Python34\lib\site-packages\django\core\handlers\base.py", line 223, in get_response
    response = middleware_method(request, response)
  File "C:\Python34\lib\site-packages\django\contrib\sessions\middleware.py", line 50, in process_response
    request.session.save()
  File "C:\Python34\lib\site-packages\django\contrib\sessions\backends\db.py", line 56, in save
    return self.create()
  File "C:\Python34\lib\site-packages\django\contrib\sessions\backends\db.py", line 37, in create
    self._session_key = self._get_new_session_key()
  File "C:\Python34\lib\site-packages\django\contrib\sessions\backends\base.py", line 155, in _get_new_session_key
    if not self.exists(session_key):
  File "C:\Python34\lib\site-packages\django\contrib\sessions\backends\db.py", line 33, in exists
    return Session.objects.filter(session_key=session_key).exists()
  File "C:\Python34\lib\site-packages\django\db\models\query.py", line 586, in exists
    return self.query.has_results(using=self.db)
  File "C:\Python34\lib\site-packages\django\db\models\sql\query.py", line 484, in has_results
    return compiler.has_results()
  File "C:\Python34\lib\site-packages\django\db\models\sql\compiler.py", line 811, in has_results
    return bool(self.execute_sql(SINGLE))
  File "C:\Python34\lib\site-packages\django\db\models\sql\compiler.py", line 829, in execute_sql
    sql, params = self.as_sql()
  File "C:\Python34\lib\site-packages\django\db\models\sql\compiler.py", line 385, in as_sql
    from_, f_params = self.get_from_clause()
  File "C:\Python34\lib\site-packages\django\db\models\sql\compiler.py", line 617, in get_from_clause
    clause_sql, clause_params = self.compile(from_clause)
  File "C:\Python34\lib\site-packages\django\db\models\sql\compiler.py", line 357, in compile
    sql, params = node.as_sql(self, self.connection)
  File "C:\Python34\lib\site-packages\django\db\models\sql\datastructures.py", line 137, in as_sql
    base_sql = compiler.quote_name_unless_alias(self.table_name)
  File "C:\Python34\lib\site-packages\django\db\models\sql\compiler.py", line 348, in quote_name_unless_alias
    r = self.connection.ops.quote_name(name)
  File "C:\Python34\lib\site-packages\django\db\backends\dummy\base.py", line 21, in complain
    raise ImproperlyConfigured("settings.DATABASES is improperly configured. "
django.core.exceptions.ImproperlyConfigured: settings.DATABASES is improperly configured. Please supply the ENGINE value. Check settings documentation for more details.
ERROR 2015-08-31 21:15:25,805 Internal Server Error: /index/login/
Traceback (most recent call last):
  File "C:\Python34\lib\site-packages\django\core\handlers\base.py", line 223, in get_response
    response = middleware_method(request, response)
  File "C:\Python34\lib\site-packages\django\contrib\sessions\middleware.py", line 50, in process_response
    request.session.save()
  File "C:\Python34\lib\site-packages\django\contrib\sessions\backends\db.py", line 56, in save
    return self.create()
  File "C:\Python34\lib\site-packages\django\contrib\sessions\backends\db.py", line 37, in create
    self._session_key = self._get_new_session_key()
  File "C:\Python34\lib\site-packages\django\contrib\sessions\backends\base.py", line 155, in _get_new_session_key
    if not self.exists(session_key):
  File "C:\Python34\lib\site-packages\django\contrib\sessions\backends\db.py", line 33, in exists
    return Session.objects.filter(session_key=session_key).exists()
  File "C:\Python34\lib\site-packages\django\db\models\query.py", line 586, in exists
    return self.query.has_results(using=self.db)
  File "C:\Python34\lib\site-packages\django\db\models\sql\query.py", line 484, in has_results
    return compiler.has_results()
  File "C:\Python34\lib\site-packages\django\db\models\sql\compiler.py", line 811, in has_results
    return bool(self.execute_sql(SINGLE))
  File "C:\Python34\lib\site-packages\django\db\models\sql\compiler.py", line 829, in execute_sql
    sql, params = self.as_sql()
  File "C:\Python34\lib\site-packages\django\db\models\sql\compiler.py", line 385, in as_sql
    from_, f_params = self.get_from_clause()
  File "C:\Python34\lib\site-packages\django\db\models\sql\compiler.py", line 617, in get_from_clause
    clause_sql, clause_params = self.compile(from_clause)
  File "C:\Python34\lib\site-packages\django\db\models\sql\compiler.py", line 357, in compile
    sql, params = node.as_sql(self, self.connection)
  File "C:\Python34\lib\site-packages\django\db\models\sql\datastructures.py", line 137, in as_sql
    base_sql = compiler.quote_name_unless_alias(self.table_name)
  File "C:\Python34\lib\site-packages\django\db\models\sql\compiler.py", line 348, in quote_name_unless_alias
    r = self.connection.ops.quote_name(name)
  File "C:\Python34\lib\site-packages\django\db\backends\dummy\base.py", line 21, in complain
    raise ImproperlyConfigured("settings.DATABASES is improperly configured. "
django.core.exceptions.ImproperlyConfigured: settings.DATABASES is improperly configured. Please supply the ENGINE value. Check settings documentation for more details.
ERROR 2015-08-31 21:15:29,318 Internal Server Error: /index/login/
Traceback (most recent call last):
  File "C:\Python34\lib\site-packages\django\core\handlers\base.py", line 223, in get_response
    response = middleware_method(request, response)
  File "C:\Python34\lib\site-packages\django\contrib\sessions\middleware.py", line 50, in process_response
    request.session.save()
  File "C:\Python34\lib\site-packages\django\contrib\sessions\backends\db.py", line 56, in save
    return self.create()
  File "C:\Python34\lib\site-packages\django\contrib\sessions\backends\db.py", line 37, in create
    self._session_key = self._get_new_session_key()
  File "C:\Python34\lib\site-packages\django\contrib\sessions\backends\base.py", line 155, in _get_new_session_key
    if not self.exists(session_key):
  File "C:\Python34\lib\site-packages\django\contrib\sessions\backends\db.py", line 33, in exists
    return Session.objects.filter(session_key=session_key).exists()
  File "C:\Python34\lib\site-packages\django\db\models\query.py", line 586, in exists
    return self.query.has_results(using=self.db)
  File "C:\Python34\lib\site-packages\django\db\models\sql\query.py", line 484, in has_results
    return compiler.has_results()
  File "C:\Python34\lib\site-packages\django\db\models\sql\compiler.py", line 811, in has_results
    return bool(self.execute_sql(SINGLE))
  File "C:\Python34\lib\site-packages\django\db\models\sql\compiler.py", line 829, in execute_sql
    sql, params = self.as_sql()
  File "C:\Python34\lib\site-packages\django\db\models\sql\compiler.py", line 385, in as_sql
    from_, f_params = self.get_from_clause()
  File "C:\Python34\lib\site-packages\django\db\models\sql\compiler.py", line 617, in get_from_clause
    clause_sql, clause_params = self.compile(from_clause)
  File "C:\Python34\lib\site-packages\django\db\models\sql\compiler.py", line 357, in compile
    sql, params = node.as_sql(self, self.connection)
  File "C:\Python34\lib\site-packages\django\db\models\sql\datastructures.py", line 137, in as_sql
    base_sql = compiler.quote_name_unless_alias(self.table_name)
  File "C:\Python34\lib\site-packages\django\db\models\sql\compiler.py", line 348, in quote_name_unless_alias
    r = self.connection.ops.quote_name(name)
  File "C:\Python34\lib\site-packages\django\db\backends\dummy\base.py", line 21, in complain
    raise ImproperlyConfigured("settings.DATABASES is improperly configured. "
django.core.exceptions.ImproperlyConfigured: settings.DATABASES is improperly configured. Please supply the ENGINE value. Check settings documentation for more details.
WARNING 2015-08-31 21:15:29,552 Not Found: /favicon.ico
WARNING 2015-08-31 21:15:33,155 Not Found: /favicon.ico
ERROR 2015-08-31 21:23:55,162 Internal Server Error: /index/logout/
Traceback (most recent call last):
  File "C:\Python34\lib\site-packages\django\core\handlers\base.py", line 132, in get_response
    response = wrapped_callback(request, *callback_args, **callback_kwargs)
  File "C:\Python34\lib\site-packages\django\views\decorators\csrf.py", line 58, in wrapped_view
    return view_func(*args, **kwargs)
  File "C:\Users\Timot\Documents\GitHub\EasyA_Web\index\views.py", line 24, in logout
    request.session.pop("isLoggedIn")
  File "C:\Python34\lib\site-packages\django\contrib\sessions\backends\base.py", line 63, in pop
    return self._session.pop(key, *args)
KeyError: 'isLoggedIn'
INFO 2015-08-31 21:25:35,627 I am here!
INFO 2015-08-31 21:25:35,627 <Response [405]>
INFO 2015-08-31 21:28:02,389 I am here!
INFO 2015-08-31 21:28:02,389 <Response [405]>
INFO 2015-08-31 21:29:46,410 I am here!
INFO 2015-08-31 21:29:46,410 <Response [405]>
INFO 2015-08-31 21:31:23,365 I am here!
INFO 2015-08-31 21:31:23,366 <Response [200]>
INFO 2015-08-31 21:31:38,018 I am here!
INFO 2015-08-31 21:31:38,018 [{'created': '2015-08-29T17:00:04.668426Z', 'last_login': '2015-08-29T17:00:04.668426Z', 'email': 'Timothy.Cardwell@gmail.com', 'id': 1, 'last_name': 'Cardwell', 'first_name': 'Timothy', 'password': 'Playstation3', 'username': 'Tim_Cardwell'}]
